Workbook

Sheet Queries
A1: Data | B1: Queries
A2: Refrence Data | B2: https://careem-insights.careem-engineering.com/sqllab?savedQueryId=432380
A3: New Launch Success | B3: https://careem-insights.careem-engineering.com/sqllab?savedQueryId=432384

Sheet Category Saturation
A1: Key | B1: Concentration Index | C1: SKU Efficiency | D1: W/D | E1: Score
A2: =B2&C2&D2 -> LowHighWidth | B2: Low | C2: High | D2: Width | E2: 100
A3: =B3&C3&D3 -> LowHighDepth | B3: Low | C3: High | D3: Depth | E3: 90
A4: =B4&C4&D4 -> LowLowWidth | B4: Low | C4: Low | D4: Width | E4: 40
A5: =B5&C5&D5 -> LowLowDepth | B5: Low | C5: Low | D5: Depth | E5: 15
A6: =B6&C6&D6 -> MediumHighWidth | B6: Medium | C6: High | D6: Width | E6: 10
A7: =B7&C7&D7 -> MediumHighDepth | B7: Medium | C7: High | D7: Depth | E7: 60
A8: =B8&C8&D8 -> MediumLowWidth | B8: Medium | C8: Low | D8: Width | E8: 25
A9: =B9&C9&D9 -> MediumLowDepth | B9: Medium | C9: Low | D9: Depth | E9: 50
A10: =B10&C10&D10 -> HighHighWidth | B10: High | C10: High | D10: Width | E10: 25
A11: =B11&C11&D11 -> HighHighDepth | B11: High | C11: High | D11: Depth | E11: 0
A12: =B12&C12&D12 -> HighLowWidth | B12: High | C12: Low | D12: Width | E12: 15
A13: =B13&C13&D13 -> HighLowDepth | B13: High | C13: Low | D13: Depth | E13: 0
B18: SATURATION MATRIX — How Concentration Index × Width/Depth → Score
B19: The New SKU Submission sheet looks up the score from the VLOOKUP table at the bottom. The visual matrix above explains the logic in plain English.
B21: HOW TO READ THIS TABLE
B22: Concentration Index = % of subcategory-bucket ROS earned by the top 20% of SKUs. If top 20% earn >70% of ROS → HIGH concentration: a few SKUs dominate. Very hard to break in. If top 20% earn 50-70% → MEDIUM: competitive but fragmented enough for a good new SKU. If top 20% earn <50% → LOW: demand genuinely spread. Most new entries find their niche. SKU Efficiency = total bucket ROS ÷ total SKUs in bucket (network units/day per SKU on average). HIGH = each slot earns ≥ 0.5/store/day on average — a productive bucket worth competing in. LOW = average slot underperforming — adding more risks further dilution. Width = SKU introduces something not currently in range at this subcat-bucket (new brand, new dietary profile, new flavour family, new format, new ingredient). Depth = SKU adds within existing coverage (another flavour variant, another size, different brand in same slot).
B25: Concentration (Do pareto SKUs hold all the demand) | C25: SKU efficiency | D25: W / D | E25: Score | F25: What it means — and what to do
B26: LOW (<50%) | C26: HIGH | D26: Width | E26: 100 | F26: Best possible entry. Market is fragmented and productive — no dominant players, every SKU earning above floor. A genuinely new addition has space to find its own demand without competing with entrenched winners.
B27: demand spread | C27: avg sku earns well | D27: Depth | E27: 100 | F27: Also clear. Fragmented + productive means another variant can still carve its own share. There are no entrenched winners to displace and the bucket can absorb it.
B28: across many SKUs | C28: LOW | D28: Width | E28: 50 | F28: Proceed carefully. Market is fragmented — no one dominates — but average SKU is weak. Width may actually improve bucket efficiency by bringing in a demand type that's missing. The right move; but the weak efficiency is a warning sign worth watching.
C29: avg sku underperforming | D29: Depth | E29: 25 | F29: Conditional. Fragmented but underperforming. The range is already diluted — adding another variant of the same thing adds to the supply side without fixing the demand problem. Needs a strong velocity signal to override.
B30: MEDIUM (50-70%) | C30: HIGH | D30: Width | E30: 100 | F30: Clear. Competitive but productive. Width enters a different demand space so it isn't fighting the existing leaders — it's finding adjacent customers the current range doesn't serve. Strong case.
B31: some leaders but | C31: avg slot earns well | D31: Depth | E31: 50 | F31: Conditional. Productive market, but Depth means competing directly with functional existing SKUs that are already earning. You need a specific reason this variant wins over what's already there. Justify differentiation explicitly.
B32: not locked | C32: LOW | D32: Width | E32: 50 | F32: Conditional. Competitive + struggling. Width is the better bet since you're not competing with the leaders for the same demand. But the underlying efficiency problem means even good SKUs struggle here. Something is structurally wrong with this bucket.
C33: avg SKU underperforming | D33: Depth | E33: 25 | F33: Review — high risk. Competitive, underperforming, and adding another variant into the same need space. This SKU is nearly certain to become slow tail. Needs exceptional velocity signal AND explicit plan to delist an offset SKU first.
B34: HIGH | C34: HIGH | D34: Width | E34: 50 | F34: Conditional — must be truly distinct. A few SKUs dominate and earn a lot. Width at least approaches from a different angle — not directly competing with the winners. But customer loyalty is already committed to the dominant SKUs. Only proceed if the Width entry is genuinely differentiated, not just a different brand of the same thing.
B35: top 20% SKUs own | C35: avg SKU earns well | D35: Depth | E35: 0 | F35: Block. Dominant SKUs own the market and every SKU is productive. Adding Depth means competing head-on with entrenched winners. Customers already prefer the dominant SKUs — your variant will not beat them. This is the most common cause of new listing failure.
B36: >70% of ROS | C36: LOW | D36: Width | E36: 25 | F36: Review — structurally broken bucket. A few SKUs dominate but the average SKU is still weak — meaning even the winners aren't winning by much. The whole bucket has a demand problem. Width gives the best shot but the structural failure means even new demand types struggle here. Very risky.
C37: avg SKU underperforming | D37: Depth | E37: 0 | F37: Block. Concentrated + underperforming = worst case. The market is locked by a few weak winners, average SKUs do nothing, and you want to add a variant. There is no commercial logic that supports this. Do not proceed regardless of supplier terms or other signals.

Sheet Depth or Width
B1: WIDTH OR DEPTH? — CM fills Yes/No for each attribute. Result is auto-calculated.
B2: WIDTH = new SKU introduces something not currently available in this subcat-bucket. DEPTH = adds within existing coverage. WIDTH additions are treated more favourably in concentrated markets (see Saturation Matrix).
B4: WHAT EACH ATTRIBUTE MEANS (read before filling the table)
B5: Attribute | C5: What YES means
B6: New Format | C6: Is the physical product format genuinely different? e.g. first protein bar in a biscuit bucket, first wafer in a chocolate bucket. Usually determined by the subcategory itself.
B7: New Brand | C7: Is this a brand not currently listed in this subcategory-bucket? A new global brand counts. A second SKU from a brand already present = No.
B8: New Flavour | C8: Does this SKU introduce a flavour FAMILY not present? e.g. first Spicy/Hot chip when only Salted/Plain and Cheese exist. Adding another BBQ variant when BBQ already exists = No. | P8: Item Description | Q8: Brand | R8: Primary Category | S8: Primary Subcategory | T8: Category | U8: Tag | V8: Addition Type | W8: Reason
B9: New Size | C9: Does this SKU introduce a pack occasion not present? The 4 occasions: Impulse <50g, Snack 50-150g, Sharing 150-400g, Gifting >400g. Another Snack when Snack already exists = No. | P9: Kamasutra Condom Ultrathin Pack of 3 pcs | Q9: Kamasutra | R9: Adult Care | S9: Condoms | T9: Condoms | V9: Depth | W9: Brand already present in subcategory "Condoms"
B10: New Ingredient | C10: Does this SKU use a base ingredient not in the bucket? e.g. first chickpea chip, first oat biscuit, first date-based bar. Standard potato/wheat/corn = No. | P10: Kamasutra Condom Ribbed Pack of 3 pcs | Q10: Kamasutra | R10: Adult Care | S10: Condoms | T10: Condoms | V10: Depth | W10: Brand already present in subcategory "Condoms"
B11: New Price Point | C11: Does this SKU fill a price gap — no existing SKU within ±2 AED in this subcat-bucket? | P11: Kamasutra Condom Intensity Pack of 3 pcs | Q11: Kamasutra | R11: Adult Care | S11: Condoms | T11: Condoms | V11: Depth | W11: Brand already present in subcategory "Condoms"
P12: Kamasutra Condom Xtra Pleasure Pack of 12 pcs | Q12: Kamasutra | R12: Adult Care | S12: Condoms | T12: Condoms | V12: Depth | W12: Brand already present in subcategory "Condoms"
B13: DECISION RULE | P13: Kamasutra Condom Xtra Pleasure Pack of 3 pcs | Q13: Kamasutra | R13: Adult Care | S13: Condoms | T13: Condoms | V13: Depth | W13: Brand already present in subcategory "Condoms"
B14: WIDTH: if any of the following = Yes → New Format, New Brand, New Flavour, New Ingredient DEPTH: if all of the above are No — only New Size or New Price Point might be Yes, or all are No. Key principle: Width = genuinely different customer need or segment. Depth = same need, another option. | P14: Kamasutra Condom Ribbed Pack of 12 pcs | Q14: Kamasutra | R14: Adult Care | S14: Condoms | T14: Condoms | V14: Depth | W14: Brand already present in subcategory "Condoms"
P15: Kamasutra Condom Dotted Pack of 3 pcs | Q15: Kamasutra | R15: Adult Care | S15: Condoms | T15: Condoms | U15: On Hold | V15: Depth | W15: Brand already present in subcategory "Condoms"
B16: SKU ATTRIBUTE TABLE — CM fills Yes/No (result auto-calculates in last column) | P16: Kamasutra Condom Wet N Wild Pack of 12 pcs | Q16: Kamasutra | R16: Adult Care | S16: Condoms | T16: Condoms | V16: Depth | W16: Brand already present in subcategory "Condoms"
B17: Proposed SKU Name | C17: New Format? | D17: New Brand? | E17: New Flavour? | F17: New Size? | G17: New Ingredient? | H17: New Price Point? | I17: WIDTH or DEPTH? (auto from cols C-H) | P17: Kamasutra Condom Wet N Wild Pack of 3 pcs | Q17: Kamasutra | R17: Adult Care | S17: Condoms | T17: Condoms | V17: Depth | W17: Brand already present in subcategory "Condoms"
B18: Enter SKU name | C18: Yes/No | D18: Yes/No | E18: Yes/No | F18: Yes/No | G18: Yes/No | H18: Yes/No | I18: Auto: Width if New Format/Brand/Flavour/Ingredient = Yes. Else Depth. | L18: Or can be done using an AI tool | P18: S-26 Gold Stage 4 ProKids, 3-6 Years 800 g | Q18: S-26 | R18: Baby Essentials | S18: Milk Formula | T18: Milk Formula | V18: Depth | W18: Brand already present in subcategory "Milk Formula"
B19: Pringles Wavy BBQ 137g | C19: No | D19: No | E19: No | F19: Yes | G19: No | H19: No | I19: Depth | P19: S-26 Gold Stage 3, 1-3 Years 1.6 kg | Q19: S-26 | R19: Baby Essentials | S19: Milk Formula | T19: Milk Formula | V19: Depth | W19: Brand already present in subcategory "Milk Formula"
B20: Takis Fuego Rolled Tortilla 92g | C20: No | D20: Yes | E20: No | F20: Yes | G20: No | H20: No | I20: Width | L20: Or simple inputs from CMs | P20: S-26 Gold Stage 1, 0-6 Months 800 g | Q20: S-26 | R20: Baby Essentials | S20: Milk Formula | T20: Milk Formula | V20: Depth | W20: Brand already present in subcategory "Milk Formula"
B21: Hippeas Chickpea Puffs 78g | C21: No | D21: Yes | E21: No | F21: No | G21: Yes | H21: No | I21: Width | P21: Cerelac Grains & Milk Pouch in Wheat & Honey 110 g | Q21: Cerelac | R21: Baby Essentials | S21: Baby Food | T21: Baby Food | V21: Depth | W21: Brand already present in subcategory "Baby Food"
B22: Doritos Dinamita Chilli Lime 127g | C22: No | D22: No | E22: No | F22: Yes | G22: No | H22: No | I22: Depth | P22: Cerelac Grains & Milk Pouch in 5 Cereals 110 g | Q22: Cerelac | R22: Baby Essentials | S22: Baby Food | T22: Baby Food | V22: Depth | W22: Brand already present in subcategory "Baby Food"
B23: Act II Butter Popcorn 100g | C23: No | D23: Yes | E23: No | F23: No | G23: No | H23: No | I23: Width | P23: Cerelac Grains & Milk Pouch in Mango 110 g | Q23: Cerelac | R23: Baby Essentials | S23: Baby Food | T23: Baby Food | V23: Depth | W23: Brand already present in subcategory "Baby Food"
B24: Skinny Pop Original 77g | C24: No | D24: Yes | E24: No | F24: No | G24: Yes | H24: No | I24: Width | P24: S-26 Gold Stage 4 Kid Dual Pack 800 g x 2 | Q24: S-26 | R24: Baby Essentials | S24: Milk Formula | T24: Milk Formula | V24: Depth | W24: Brand already present in subcategory "Milk Formula"
B25: Cheetos Flamin Hot 80g | C25: No | D25: No | E25: No | F25: Yes | G25: No | H25: No | I25: Depth | P25: Cerelac Fruits Puree Pouch in Banana, Apple, Orange & Biscuit Value Pack 90 g x 4 | Q25: Cerelac | R25: Baby Essentials | S25: Baby Food | T25: Baby Food | U25: Phase Out | V25: Depth | W25: Brand already present in subcategory "Baby Food"
B26: Bayara Cashews Roasted 300g | C26: No | D26: No | E26: No | F26: No | G26: No | H26: Yes | I26: Depth | P26: Gerber Organic Puree Pouch in Mango 90 g x 4 | Q26: Gerber | R26: Baby Essentials | S26: Baby Food | T26: Baby Food | U26: Phase Out | V26: Depth | W26: Brand already present in subcategory "Baby Food"
B27: Blue Diamond Almonds Smokehouse 170g | C27: No | D27: Yes | E27: No | F27: Yes | G27: No | H27: No | I27: Width | P27: Cerelac Fruits Puree Pouch in Apple, Carrot & Mango Value Pack 90 g x 4 | Q27: Cerelac | R27: Baby Essentials | S27: Baby Food | T27: Baby Food | U27: Phase Out | V27: Depth | W27: Brand already present in subcategory "Baby Food"
B28: Wonderful Pistachios 113g | C28: No | D28: Yes | E28: No | F28: No | G28: Yes | H28: No | I28: Width | P28: Be Fit Brown Pita Wrapper | Q28: Befit | R28: Bakery | S28: Tortilla & Wraps | T28: Tortilla & Wraps | U28: Phase Out | V28: Depth | W28: Brand already present in subcategory "Tortilla & Wraps"
B29: Halabi Premium Nuts Tin 400g | C29: No | D29: No | E29: No | F29: No | G29: No | H29: No | I29: Depth | P29: Special Ginger House Assembled | Q29: Bakemart | R29: Bakery | S29: Cakes, Croissants & Pastries | T29: Cakes, Croissants & Pastries | U29: Phase Out | V29: Depth | W29: Brand already present in subcategory "Cakes, Croissants & Pastries"
B30: Ritz Crisp Thins Sea Salt 105g | C30: No | D30: Yes | E30: No | F30: No | G30: No | H30: No | I30: Width | P30: Special Ginger House Kit | Q30: Bakemart | R30: Bakery | S30: Cakes, Croissants & Pastries | T30: Cakes, Croissants & Pastries | V30: Depth | W30: Brand already present in subcategory "Cakes, Croissants & Pastries"
B31: Snyder's Pretzels Honey Mustard 125g | C31: No | D31: Yes | E31: No | F31: Yes | G31: No | H31: No | I31: Width | P31: Plum Cake Rich Fruit-Mono Portion | Q31: Bakemart | R31: Bakery | S31: Cakes, Croissants & Pastries | T31: Cakes, Croissants & Pastries | V31: Depth | W31: Brand already present in subcategory "Cakes, Croissants & Pastries"
B32: Doritos Family Pack Nacho 300g | C32: No | D32: No | E32: No | F32: No | G32: No | H32: Yes | I32: Depth | P32: Christmas Pudding | Q32: Bakemart | R32: Bakery | S32: Cakes, Croissants & Pastries | T32: Cakes, Croissants & Pastries | U32: Phase Out | V32: Depth | W32: Brand already present in subcategory "Cakes, Croissants & Pastries"
B33: Hunter's Gourmet Truffle Chips 100g | C33: No | D33: Yes | E33: No | F33: Yes | G33: No | H33: No | I33: Width | P33: Mince Pie | Q33: Bakemart | R33: Bakery | S33: Cakes, Croissants & Pastries | T33: Cakes, Croissants & Pastries | U33: Phase Out | V33: Depth | W33: Brand already present in subcategory "Cakes, Croissants & Pastries"
B34: Kurkure Masala Munch 65g | C34: No | D34: Yes | E34: No | F34: Yes | G34: No | H34: No | I34: Width | P34: Bread Stollen Small | Q34: Bakemart | R34: Bakery | S34: Breads & Loaves | T34: Breads & Loaves | U34: Phase Out | V34: Depth | W34: Brand already present in subcategory "Breads & Loaves"
B35: Tom Tom Chilli Chips 90g | C35: No | D35: Yes | E35: No | F35: No | G35: No | H35: No | I35: Width | P35: Cookies Stollen | Q35: Bakemart | R35: Bakery | S35: Rusk, Cookies & Crackers | T35: Rusk, Cookies & Crackers | U35: Phase Out | V35: Width | W35: Brand exists but enters new subcategory "Rusk, Cookies & Crackers"
B36: Pringles Sour Cream Mini 40g | C36: No | D36: No | E36: No | F36: No | G36: No | H36: Yes | I36: Depth | P36: Cookie Cinnamon Coin | Q36: Bakemart | R36: Bakery | S36: Rusk, Cookies & Crackers | T36: Rusk, Cookies & Crackers | U36: Phase Out | V36: Width | W36: Brand exists but enters new subcategory "Rusk, Cookies & Crackers"
B37: Lay's Family Pack Salt 250g | C37: No | D37: No | E37: No | F37: No | G37: No | H37: Yes | I37: Depth | P37: Xmas Cookie Printed - Ginger Man | Q37: Bakemart | R37: Bakery | S37: Rusk, Cookies & Crackers | T37: Rusk, Cookies & Crackers | U37: Phase Out | V37: Width | W37: Brand exists but enters new subcategory "Rusk, Cookies & Crackers"
B38: Beanitos White Bean Chips 113g | C38: No | D38: Yes | E38: No | F38: No | G38: Yes | H38: No | I38: Width | P38: Xmas Cookie - Santa Head Printed | Q38: Bakemart | R38: Bakery | S38: Rusk, Cookies & Crackers | T38: Rusk, Cookies & Crackers | U38: Phase Out | V38: Width | W38: Brand exists but enters new subcategory "Rusk, Cookies & Crackers"
B39: KitKat Gold Caramel 45g | C39: No | D39: No | E39: No | F39: Yes | G39: No | H39: No | I39: Depth | P39: Snowman Cookies in Bag | Q39: Bakemart | R39: Bakery | S39: Rusk, Cookies & Crackers | T39: Rusk, Cookies & Crackers | U39: Phase Out | V39: Width | W39: Brand exists but enters new subcategory "Rusk, Cookies & Crackers"
B40: Kinder Happy Hippos 103g | C40: No | D40: No | E40: No | F40: Yes | G40: No | H40: No | I40: Depth | P40: Panettone Chocolate - Large | Q40: Bakemart | R40: Bakery | S40: Cakes, Croissants & Pastries | T40: Cakes, Croissants & Pastries | U40: Phase Out | V40: Depth | W40: Brand already present in subcategory "Cakes, Croissants & Pastries"
B41: Milka Daim 100g | C41: No | D41: No | E41: No | F41: Yes | G41: No | H41: No | I41: Depth | P41: Panettone Mix Fruit - Large | Q41: Bakemart | R41: Bakery | S41: Cakes, Croissants & Pastries | T41: Cakes, Croissants & Pastries | U41: Phase Out | V41: Depth | W41: Brand already present in subcategory "Cakes, Croissants & Pastries"
...

Sheet Monetization
A1: Types | B1: Score
A2: Promo Calendar Committed | B2: 75
A3: Trade Funding | B3: 100
A4: Ads Support | B4: 100
A5: No Support | B5: 0

Sheet Refrence Data
A1: Category_ASP Key | B1: Subcat_ASP Key | C1: Parent Category | D1: Sub Category | E1: ASP Bucket | F1: Count of SKUs (Avail >50%) | G1: Count of Non-Moving SKUs | H1: Total Onhand | I1: Non-Moving Onhand | J1: Total ROS (L14D) | K1: Total ROS (L30D) | L1: Total ROS (L60D) | M1: ROS of Top 20% SKUs | N1: Concentration Index | O1: P10 ROS (All) | P1: P20 ROS (All) | Q1: P30 ROS (All) | R1: P50 ROS (All) | S1: P70 ROS (All) | T1: P10 ROS (Moving) | U1: P20 ROS (Moving) | V1: P30 ROS (Moving) | W1: P50 ROS (Moving) | X1: P70 ROS (Moving) | Y1: SKU Efficiency | Z1: Sub Category P50 ROS (All) | AA1: Sub Category P50 ROS (Moving) | AB1: Sub Category SKU Efficiency | AC1: Sub Category Median SKU Efficiency | AD1: Category-ASP P50 ROS (All) | AE1: Category-ASP P50 ROS (Moving) | AF1: Category-ASP SKU Efficiency | AG1: Category-ASP Median SKU Efficiency | AH1: Parent Category P50 ROS (All) | AI1: Parent Category P50 ROS (Moving) | AJ1: Parent Category SKU Efficiency | AK1: Parent Category Median SKU Efficiency | AL1: Run Date
A2: _10-15 | B2: _10-15 | E2: 46310 | F2: 1 | G2: 0 | H2: 0 | I2: 0 | J2: 0.267857 | K2: 0.085145 | L2: 0.051957 | M2: 0.085145 | N2: 1 | O2: 0.085145 | P2: 0.085145 | Q2: 0.085145 | R2: 0.085145 | S2: 0.085145 | T2: 0.085145 | U2: 0.085145 | V2: 0.085145 | W2: 0.085145 | X2: 0.085145 | Y2: 0.085145 | Z2: 0 | AA2: 0.1 | AB2: 0.001517 | AC2: 0.004412 | AD2: 0.085145 | AE2: 0.085145 | AF2: 0.085145 | AG2: 0.085145 | AH2: 0 | AI2: 0.1 | AJ2: 0.001517 | AK2: 0.004412 | AL2: #########
A3: _20-25 | B3: _20-25 | E3: 20-25 | F3: 3 | G3: 0 | H3: 436 | I3: 0 | J3: 0.285714 | K3: 0.332258 | L3: 0.386348 | M3: 0.232258 | N3: 0.699029 | O3: 0 | P3: 0 | Q3: 0 | R3: 0.1 | S3: 0.232258 | T3: 0.1 | U3: 0.1 | V3: 0.1 | W3: 0.232258 | X3: 0.232258 | Y3: 0.110753 | Z3: 0 | AA3: 0.1 | AB3: 0.001517 | AC3: 0.004412 | AD3: 0.1 | AE3: 0.232258 | AF3: 0.110753 | AG3: 0.110753 | AH3: 0 | AI3: 0.1 | AJ3: 0.001517 | AK3: 0.004412 | AL3: #########
A4: _25+ | B4: _25+ | E4: 25+ | F4: 68 | G4: 0 | H4: 529 | I4: 0 | J4: 0.285714 | K4: 0.3 | L4: 0.352276 | M4: 0.3 | N4: 1 | O4: 0 | P4: 0 | Q4: 0 | R4: 0 | S4: 0 | T4: 0.033333 | U4: 0.033333 | V4: 0.033333 | W4: 0.1 | X4: 0.166667 | Y4: 0.004412 | Z4: 0 | AA4: 0.1 | AB4: 0.001517 | AC4: 0.004412 | AD4: 0 | AE4: 0.1 | AF4: 0.004412 | AG4: 0.004412 | AH4: 0 | AI4: 0.1 | AJ4: 0.001517 | AK4: 0.004412 | AL4: #########
A5: _5-10 | B5: _5-10 | E5: 46300 | F5: 1 | G5: 0 | H5: 0 | I5: 0 | J5: 0 | K5: 0 | L5: 0 | M5: 0 | N5: 0 | O5: 0 | P5: 0 | Q5: 0 | R5: 0 | S5: 0 | T5: 0 | U5: 0 | V5: 0 | W5: 0 | X5: 0 | Y5: 0 | Z5: 0 | AA5: 0.1 | AB5: 0.001517 | AC5: 0.004412 | AD5: 0 | AE5: 0 | AF5: 0 | AG5: 0 | AH5: 0 | AI5: 0.1 | AJ5: 0.001517 | AK5: 0.004412 | AL5: #########
A6: _Unknown | B6: _Unknown | E6: Unknown | F6: 400 | G6: 2 | H6: 112 | I6: 112 | J6: 0 | K6: 0 | L6: 0 | M6: 0 | N6: 0 | O6: 0 | P6: 0 | Q6: 0 | R6: 0 | S6: 0 | T6: 0 | U6: 0 | V6: 0 | W6: 0 | X6: 0 | Y6: 0 | Z6: 0 | AA6: 0.1 | AB6: 0.001517 | AC6: 0.004412 | AD6: 0 | AE6: 0 | AF6: 0 | AG6: 0 | AH6: 0 | AI6: 0.1 | AJ6: 0.001517 | AK6: 0.004412 | AL6: #########
A7: Adult Care_20-25 | B7: Accessories_20-25 | C7: Adult Care | D7: Accessories | E7: 20-25 | F7: 1 | G7: 0 | H7: 0 | I7: 0 | J7: 0.076923 | K7: 2.034483 | L7: 0.118502 | M7: 2.034483 | N7: 1 | O7: 2.034483 | P7: 2.034483 | Q7: 2.034483 | R7: 2.034483 | S7: 2.034483 | T7: 2.034483 | U7: 2.034483 | V7: 2.034483 | W7: 2.034483 | X7: 2.034483 | Y7: 2.034483 | Z7: 0 | AA7: 2.034483 | AB7: 0.093992 | AC7: 0 | AD7: 2.034483 | AE7: 2.034483 | AF7: 1.703893 | AG7: 2.034483 | AH7: 1.849147 | AI7: 3.582599 | AJ7: 3.244024 | AK7: 2.034483 | AL7: #########
A8: Adult Care_25+ | B8: Accessories_25+ | C8: Adult Care | D8: Accessories | E8: 25+ | F8: 1 | G8: 0 | H8: 0 | I8: 0 | J8: 0 | K8: 0 | L8: 0.090909 | M8: 0 | N8: 0 | O8: 0 | P8: 0 | Q8: 0 | R8: 0 | S8: 0 | T8: 0 | U8: 0 | V8: 0 | W8: 0 | X8: 0 | Y8: 0 | Z8: 0 | AA8: 2.034483 | AB8: 0.093992 | AC8: 0 | AD8: 3.413527 | AE8: 3.582599 | AF8: 4.587337 | AG8: 3.737092 | AH8: 1.849147 | AI8: 3.582599 | AJ8: 3.244024 | AK8: 2.034483 | AL8: #########
A9: Adult Care_Unknown | B9: Accessories_Unknown | C9: Adult Care | D9: Accessories | E9: Unknown | F9: 1 | G9: 0 | H9: 0 | I9: 0 | J9: 0 | K9: 0 | L9: 0 | M9: 0 | N9: 0 | O9: 0 | P9: 0 | Q9: 0 | R9: 0 | S9: 0 | T9: 0 | U9: 0 | V9: 0 | W9: 0 | X9: 0 | Y9: 0 | Z9: 0 | AA9: 2.034483 | AB9: 0.093992 | AC9: 0 | AD9: 0 | AE9: 0 | AF9: 0 | AG9: 0 | AH9: 1.849147 | AI9: 3.582599 | AJ9: 3.244024 | AK9: 2.034483 | AL9: #########
A10: Adult Care_15-20 | B10: Condoms_15-20 | C10: Adult Care | D10: Condoms | E10: 15-20 | F10: 3 | G10: 0 | H10: 2144 | I10: 0 | J10: 14.95384 | K10: 13.47098 | L10: 14.19314 | M10: 6.131733 | N10: 0.455181 | O10: 2.696133 | P10: 2.696133 | Q10: 2.696133 | R10: 4.643116 | S10: 6.131733 | T10: 2.696133 | U10: 2.696133 | V10: 2.696133 | W10: 4.643116 | X10: 6.131733 | Y10: 4.490327 | Z10: 3.413527 | AA10: 4.407286 | AB10: 4.118029 | AC10: 4.490327 | AD10: 4.643116 | AE10: 4.643116 | AF10: 4.490327 | AG10: 4.490327 | AH10: 1.849147 | AI10: 3.582599 | AJ10: 3.244024 | AK10: 2.034483 | AL10: #########
A11: Adult Care_20-25 | B11: Condoms_20-25 | C11: Adult Care | D11: Condoms | E11: 20-25 | F11: 1 | G11: 0 | H11: 126 | I11: 0 | J11: 1.72381 | K11: 1.373303 | L11: 1.499379 | M11: 1.373303 | N11: 1 | O11: 1.373303 | P11: 1.373303 | Q11: 1.373303 | R11: 1.373303 | S11: 1.373303 | T11: 1.373303 | U11: 1.373303 | V11: 1.373303 | W11: 1.373303 | X11: 1.373303 | Y11: 1.373303 | Z11: 3.413527 | AA11: 4.407286 | AB11: 4.118029 | AC11: 4.490327 | AD11: 2.034483 | AE11: 2.034483 | AF11: 1.703893 | AG11: 2.034483 | AH11: 1.849147 | AI11: 3.582599 | AJ11: 3.244024 | AK11: 2.034483 | AL11: #########
A12: Adult Care_25+ | B12: Condoms_25+ | C12: Adult Care | D12: Condoms | E12: 25+ | F12: 15 | G12: 0 | H12: 7866 | I12: 0 | J12: 81.20115 | K12: 81.0496 | L12: 80.08067 | M12: 36.67825 | N12: 0.452541 | O12: 0.668966 | P12: 1.849147 | Q12: 2.076899 | R12: 3.820168 | S12: 7.620216 | T12: 0.668966 | U12: 1.849147 | V12: 2.076899 | W12: 3.820168 | X12: 7.620216 | Y12: 5.403307 | Z12: 3.413527 | AA12: 4.407286 | AB12: 4.118029 | AC12: 4.490327 | AD12: 3.413527 | AE12: 3.582599 | AF12: 4.587337 | AG12: 3.737092 | AH12: 1.849147 | AI12: 3.582599 | AJ12: 3.244024 | AK12: 2.034483 | AL12: #########
A13: Adult Care_5-10 | B13: Condoms_5-10 | C13: Adult Care | D13: Condoms | E13: 46300 | F13: 2 | G13: 0 | H13: 66 | I13: 0 | J13: 5.472222 | K13: 11.17486 | L13: 9.91429 | M13: 11.17486 | N13: 1 | O13: 0 | P13: 0 | Q13: 0 | R13: 11.17486 | S13: 11.17486 | T13: 11.17486 | U13: 11.17486 | V13: 11.17486 | W13: 11.17486 | X13: 11.17486 | Y13: 5.587432 | Z13: 3.413527 | AA13: 4.407286 | AB13: 4.118029 | AC13: 4.490327 | AD13: 11.17486 | AE13: 11.17486 | AF13: 5.587432 | AG13: 5.587432 | AH13: 1.849147 | AI13: 3.582599 | AJ13: 3.244024 | AK13: 2.034483 | AL13: #########
A14: Adult Care_Unknown | B14: Condoms_Unknown | C14: Adult Care | D14: Condoms | E14: Unknown | F14: 5 | G14: 0 | H14: 0 | I14: 0 | J14: 0 | K14: 0 | L14: 0 | M14: 0 | N14: 0 | O14: 0 | P14: 0 | Q14: 0 | R14: 0 | S14: 0 | T14: 0 | U14: 0 | V14: 0 | W14: 0 | X14: 0 | Y14: 0 | Z14: 3.413527 | AA14: 4.407286 | AB14: 4.118029 | AC14: 4.490327 | AD14: 0 | AE14: 0 | AF14: 0 | AG14: 0 | AH14: 1.849147 | AI14: 3.582599 | AJ14: 3.244024 | AK14: 2.034483 | AL14: #########
A15: Adult Care_25+ | B15: Lubricants_25+ | C15: Adult Care | D15: Lubricants | E15: 25+ | F15: 9 | G15: 0 | H15: 3759 | I15: 0 | J15: 34.54381 | K15: 33.63383 | L15: 34.1862 | M15: 20.07087 | N15: 0.596747 | O15: 0 | P15: 0.932258 | Q15: 1.033333 | R15: 3 | S15: 3.6171 | T15: 0.932258 | U15: 1.033333 | V15: 1.768454 | W15: 3.211812 | X15: 3.6171 | Y15: 3.737092 | Z15: 0.932258 | AA15: 3.211812 | AB15: 2.242255 | AC15: 3.737092 | AD15: 3.413527 | AE15: 3.582599 | AF15: 4.587337 | AG15: 3.737092 | AH15: 1.849147 | AI15: 3.582599 | AJ15: 3.244024 | AK15: 2.034483 | AL15: #########
A16: Adult Care_Unknown | B16: Lubricants_Unknown | C16: Adult Care | D16: Lubricants | E16: Unknown | F16: 6 | G16: 0 | H16: 0 | I16: 0 | J16: 0 | K16: 0 | L16: 0 | M16: 0 | N16: 0 | O16: 0 | P16: 0 | Q16: 0 | R16: 0 | S16: 0 | T16: 0 | U16: 0 | V16: 0 | W16: 0 | X16: 0 | Y16: 0 | Z16: 0.932258 | AA16: 3.211812 | AB16: 2.242255 | AC16: 3.737092 | AD16: 0 | AE16: 0 | AF16: 0 | AG16: 0 | AH16: 1.849147 | AI16: 3.582599 | AJ16: 3.244024 | AK16: 2.034483 | AL16: #########
A17: Baby Essentials_Unknown | B17: Accessories_Unknown | C17: Baby Essentials | D17: Accessories | E17: Unknown | F17: 1 | G17: 0 | H17: 0 | I17: 0 | J17: 0 | K17: 0 | L17: 0 | M17: 0 | N17: 0 | O17: 0 | P17: 0 | Q17: 0 | R17: 0 | S17: 0 | T17: 0 | U17: 0 | V17: 0 | W17: 0 | X17: 0 | Y17: 0 | Z17: 0 | AA17: 2.034483 | AB17: 0.093992 | AC17: 0 | AD17: 0 | AE17: 0 | AF17: 0 | AG17: 0 | AH17: 0 | AI17: 1.944494 | AJ17: 1.674894 | AK17: 0.852062 | AL17: #########
A18: Baby Essentials_0-5 | B18: Baby Bath & Shower_0-5 | C18: Baby Essentials | D18: Baby Bath & Shower | E18: 0-5 | F18: 1 | G18: 0 | H18: 1064 | I18: 0 | J18: 6.665784 | K18: 6.742408 | L18: 7.155114 | M18: 6.742408 | N18: 1 | O18: 6.742408 | P18: 6.742408 | Q18: 6.742408 | R18: 6.742408 | S18: 6.742408 | T18: 6.742408 | U18: 6.742408 | V18: 6.742408 | W18: 6.742408 | X18: 6.742408 | Y18: 6.742408 | Z18: 0.467593 | AA18: 0.907405 | AB18: 0.942045 | AC18: 0.852062 | AD18: 6.742408 | AE18: 13.98243 | AF18: 9.244738 | AG18: 6.742408 | AH18: 0 | AI18: 1.944494 | AJ18: 1.674894 | AK18: 0.852062 | AL18: #########
A19: Baby Essentials_10-15 | B19: Baby Bath & Shower_10-15 | C19: Baby Essentials | D19: Baby Bath & Shower | E19: 46310 | F19: 2 | G19: 0 | H19: 42 | I19: 0 | J19: 0.468254 | K19: 0.773333 | L19: 0.518926 | M19: 0.733333 | N19: 0.948276 | O19: 0.04 | P19: 0.04 | Q19: 0.04 | R19: 0.733333 | S19: 0.733333 | T19: 0.04 | U19: 0.04 | V19: 0.04 | W19: 0.733333 | X19: 0.733333 | Y19: 0.386667 | Z19: 0.467593 | AA19: 0.907405 | AB19: 0.942045 | AC19: 0.852062 | AD19: 4.940896 | AE19: 5.044467 | AF19: 6.358956 | AG19: 5.817529 | AH19: 0 | AI19: 1.944494 | AJ19: 1.674894 | AK19: 0.852062 | AL19: #########
A20: Baby Essentials_15-20 | B20: Baby Bath & Shower_15-20 | C20: Baby Essentials | D20: Baby Bath & Shower | E20: 15-20 | F20: 2 | G20: 0 | H20: 377 | I20: 0 | J20: 1.979853 | K20: 1.704125 | L20: 1.760484 | M20: 1.365236 | N20: 0.801136 | O20: 0.338889 | P20: 0.338889 | Q20: 0.338889 | R20: 1.365236 | S20: 1.365236 | T20: 0.338889 | U20: 0.338889 | V20: 0.338889 | W20: 1.365236 | X20: 1.365236 | Y20: 0.852062 | Z20: 0.467593 | AA20: 0.907405 | AB20: 0.942045 | AC20: 0.852062 | AD20: 0.919298 | AE20: 1.380698 | AF20: 2.165781 | AG20: 2.559953 | AH20: 0 | AI20: 1.944494 | AJ20: 1.674894 | AK20: 0.852062 | AL20: #########
A21: Baby Essentials_20-25 | B21: Baby Bath & Shower_20-25 | C21: Baby Essentials | D21: Baby Bath & Shower | E21: 20-25 | F21: 4 | G21: 0 | H21: 852 | I21: 0 | J21: 7.243529 | K21: 5.854608 | L21: 5.450274 | M21: 3.270005 | N21: 0.558535 | O21: 0.249957 | P21: 0.249957 | Q21: 0.309804 | R21: 2.024842 | S21: 2.024842 | T21: 0.249957 | U21: 0.249957 | V21: 0.309804 | W21: 2.024842 | X21: 2.024842 | Y21: 1.463652 | Z21: 0.467593 | AA21: 0.907405 | AB21: 0.942045 | AC21: 0.852062 | AD21: 0.604598 | AE21: 1.075268 | AF21: 2.905084 | AG21: 1.036618 | AH21: 0 | AI21: 1.944494 | AJ21: 1.674894 | AK21: 0.852062 | AL21: #########
A22: Baby Essentials_25+ | B22: Baby Bath & Shower_25+ | C22: Baby Essentials | D22: Baby Bath & Shower | E22: 25+ | F22: 7 | G22: 0 | H22: 1000 | I22: 0 | J22: 6.339069 | K22: 5.650506 | L22: 5.132868 | M22: 2.024209 | N22: 0.358235 | O22: 0.466889 | P22: 0.467593 | Q22: 0.818519 | R22: 0.907405 | S22: 0.965891 | T22: 0.466889 | U22: 0.467593 | V22: 0.818519 | W22: 0.907405 | X22: 0.965891 | Y22: 0.807215 | Z22: 0.467593 | AA22: 0.907405 | AB22: 0.942045 | AC22: 0.852062 | AD22: 0.819971 | AE22: 1.223488 | AF22: 1.50437 | AG22: 1.524539 | AH22: 0 | AI22: 1.944494 | AJ22: 1.674894 | AK22: 0.852062 | AL22: #########
A23: Baby Essentials_Unknown | B23: Baby Bath & Shower_Unknown | C23: Baby Essentials | D23: Baby Bath & Shower | E23: Unknown | F23: 6 | G23: 1 | H23: 173 | I23: 173 | J23: 0 | K23: 0 | L23: 0 | M23: 0 | N23: 0 | O23: 0 | P23: 0 | Q23: 0 | R23: 0 | S23: 0 | T23: 0 | U23: 0 | V23: 0 | W23: 0 | X23: 0 | Y23: 0 | Z23: 0.467593 | AA23: 0.907405 | AB23: 0.942045 | AC23: 0.852062 | AD23: 0 | AE23: 0 | AF23: 0 | AG23: 0 | AH23: 0 | AI23: 1.944494 | AJ23: 1.674894 | AK23: 0.852062 | AL23: #########
A24: Baby Essentials_10-15 | B24: Baby Care_10-15 | C24: Baby Essentials | D24: Baby Care | E24: 46310 | F24: 2 | G24: 0 | H24: 295 | I24: 0 | J24: 0.836508 | K24: 0.83352 | L24: 0.878924 | M24: 0.628758 | N24: 0.754341 | O24: 0.204762 | P24: 0.204762 | Q24: 0.204762 | R24: 0.628758 | S24: 0.628758 | T24: 0.204762 | U24: 0.204762 | V24: 0.204762 | W24: 0.628758 | X24: 0.628758 | Y24: 0.41676 | Z24: 0.033333 | AA24: 0.5 | AB24: 0.391923 | AC24: 0.41676 | AD24: 4.940896 | AE24: 5.044467 | AF24: 6.358956 | AG24: 5.817529 | AH24: 0 | AI24: 1.944494 | AJ24: 1.674894 | AK24: 0.852062 | AL24: #########
A25: Baby Essentials_15-20 | B25: Baby Care_15-20 | C25: Baby Essentials | D25: Baby Care | E25: 15-20 | F25: 6 | G25: 0 | H25: 408 | I25: 0 | J25: 2.612338 | K25: 4.248377 | L25: 5.011963 | M25: 3.330643 | N25: 0.78398 | O25: 0 | P25: 0 | Q25: 0 | R25: 0.5 | S25: 1.380698 | T25: 0.417734 | U25: 0.417734 | V25: 0.5 | W25: 1.380698 | X25: 1.380698 | Y25: 0.708063 | Z25: 0.033333 | AA25: 0.5 | AB25: 0.391923 | AC25: 0.41676 | AD25: 0.919298 | AE25: 1.380698 | AF25: 2.165781 | AG25: 2.559953 | AH25: 0 | AI25: 1.944494 | AJ25: 1.674894 | AK25: 0.852062 | AL25: #########
A26: Baby Essentials_20-25 | B26: Baby Care_20-25 | C26: Baby Essentials | D26: Baby Care | E26: 20-25 | F26: 3 | G26: 0 | H26: 110 | I26: 0 | J26: 0.896825 | K26: 1.018309 | L26: 2.470283 | M26: 0.572991 | N26: 0.562689 | O26: 0 | P26: 0 | Q26: 0 | R26: 0.445317 | S26: 0.572991 | T26: 0.445317 | U26: 0.445317 | V26: 0.445317 | W26: 0.572991 | X26: 0.572991 | Y26: 0.339436 | Z26: 0.033333 | AA26: 0.5 | AB26: 0.391923 | AC26: 0.41676 | AD26: 0.604598 | AE26: 1.075268 | AF26: 2.905084 | AG26: 1.036618 | AH26: 0 | AI26: 1.944494 | AJ26: 1.674894 | AK26: 0.852062 | AL26: #########
A27: Baby Essentials_25+ | B27: Baby Care_25+ | C27: Baby Essentials | D27: Baby Care | E27: 25+ | F27: 17 | G27: 0 | H27: 2346 | I27: 0 | J27: 11.15745 | K27: 11.92824 | L27: 13.27689 | M27: 7.785888 | N27: 0.652727 | O27: 0 | P27: 0.033333 | Q27: 0.066667 | R27: 0.280952 | S27: 0.907405 | T27: 0.033333 | U27: 0.066667 | V27: 0.142857 | W27: 0.366667 | X27: 1.196848 | Y27: 0.701661 | Z27: 0.033333 | AA27: 0.5 | AB27: 0.391923 | AC27: 0.41676 | AD27: 0.819971 | AE27: 1.223488 | AF27: 1.50437 | AG27: 1.524539 | AH27: 0 | AI27: 1.944494 | AJ27: 1.674894 | AK27: 0.852062 | AL27: #########
A28: Baby Essentials_Unknown | B28: Baby Care_Unknown | C28: Baby Essentials | D28: Baby Care | E28: Unknown | F28: 18 | G28: 1 | H28: 34 | I28: 34 | J28: 0 | K28: 0 | L28: 0 | M28: 0 | N28: 0 | O28: 0 | P28: 0 | Q28: 0 | R28: 0 | S28: 0 | T28: 0 | U28: 0 | V28: 0 | W28: 0 | X28: 0 | Y28: 0 | Z28: 0.033333 | AA28: 0.5 | AB28: 0.391923 | AC28: 0.41676 | AD28: 0 | AE28: 0 | AF28: 0 | AG28: 0 | AH28: 0 | AI28: 1.944494 | AJ28: 1.674894 | AK28: 0.852062 | AL28: #########
A29: Baby Essentials_0-5 | B29: Baby Food_0-5 | C29: Baby Essentials | D29: Baby Food | E29: 0-5 | F29: 2 | G29: 0 | H29: 3162 | I29: 0 | J29: 42.18712 | K29: 39.48128 | L29: 39.13113 | M29: 25.49885 | N29: 0.645847 | O29: 13.98243 | P29: 13.98243 | Q29: 13.98243 | R29: 25.49885 | S29: 25.49885 | T29: 13.98243 | U29: 13.98243 | V29: 13.98243 | W29: 25.49885 | X29: 25.49885 | Y29: 19.74064 | Z29: 0 | AA29: 4.700865 | AB29: 2.072861 | AC29: 2.559953 | AD29: 6.742408 | AE29: 13.98243 | AF29: 9.244738 | AG29: 6.742408 | AH29: 0 | AI29: 1.944494 | AJ29: 1.674894 | AK29: 0.852062 | AL29: #########
A30: Baby Essentials_10-15 | B30: Baby Food_10-15 | C30: Baby Essentials | D30: Baby Food | E30: 46310 | F30: 20 | G30: 0 | H30: 10154 | I30: 0 | J30: 115.4056 | K30: 116.3506 | L30: 117.5589 | M30: 37.94324 | N30: 0.326111 | O30: 2.113793 | P30: 3.277392 | Q30: 3.852793 | R30: 6.018057 | S30: 8.02561 | T30: 2.113793 | U30: 3.277392 | V30: 3.852793 | W30: 6.018057 | X30: 8.02561 | Y30: 5.817529 | Z30: 0 | AA30: 4.700865 | AB30: 2.072861 | AC30: 2.559953 | AD30: 4.940896 | AE30: 5.044467 | AF30: 6.358956 | AG30: 5.817529 | AH30: 0 | AI30: 1.944494 | AJ30: 1.674894 | AK30: 0.852062 | AL30: #########
A31: Baby Essentials_15-20 | B31: Baby Food_15-20 | C31: Baby Essentials | D31: Baby Food | E31: 15-20 | F31: 6 | G31: 0 | H31: 1030 | I31: 0 | J31: 21.28644 | K31: 15.35972 | L31: 13.99204 | M31: 10.19609 | N31: 0.66382 | O31: 0 | P31: 0.25 | Q31: 0.25 | R31: 3.277122 | S31: 3.441991 | T31: 0.25 | U31: 1.636508 | V31: 1.636508 | W31: 3.277122 | X31: 3.441991 | Y31: 2.559953 | Z31: 0 | AA31: 4.700865 | AB31: 2.072861 | AC31: 2.559953 | AD31: 0.919298 | AE31: 1.380698 | AF31: 2.165781 | AG31: 2.559953 | AH31: 0 | AI31: 1.944494 | AJ31: 1.674894 | AK31: 0.852062 | AL31: #########
A32: Baby Essentials_20-25 | B32: Baby Food_20-25 | C32: Baby Essentials | D32: Baby Food | E32: 20-25 | F32: 5 | G32: 0 | H32: 532 | I32: 0 | J32: 3.931319 | K32: 5.183091 | L32: 4.518586 | M32: 1.839733 | N32: 0.354949 | O32: 0 | P32: 0.604598 | Q32: 0.604598 | R32: 1.075268 | S32: 1.663492 | T32: 0.604598 | U32: 0.604598 | V32: 1.075268 | W32: 1.663492 | X32: 1.663492 | Y32: 1.036618 | Z32: 0 | AA32: 4.700865 | AB32: 2.072861 | AC32: 2.559953 | AD32: 0.604598 | AE32: 1.075268 | AF32: 2.905084 | AG32: 1.036618 | AH32: 0 | AI32: 1.944494 | AJ32: 1.674894 | AK32: 0.852062 | AL32: #########
A33: Baby Essentials_25+ | B33: Baby Food_25+ | C33: Baby Essentials | D33: Baby Food | E33: 25+ | F33: 23 | G33: 0 | H33: 5716 | I33: 0 | J33: 25.61588 | K33: 24.61555 | L33: 25.96152 | M33: 11.85411 | N33: 0.48157 | O33: 0 | P33: 0.333333 | Q33: 0.485965 | R33: 0.801372 | S33: 1.475322 | T33: 0.398925 | U33: 0.569342 | V33: 0.629032 | W33: 1.224731 | X33: 1.669429 | Y33: 1.070241 | Z33: 0 | AA33: 4.700865 | AB33: 2.072861 | AC33: 2.559953 | AD33: 0.819971 | AE33: 1.223488 | AF33: 1.50437 | AG33: 1.524539 | AH33: 0 | AI33: 1.944494 | AJ33: 1.674894 | AK33: 0.852062 | AL33: #########
A34: Baby Essentials_5-10 | B34: Baby Food_5-10 | C34: Baby Essentials | D34: Baby Food | E34: 46300 | F34: 38 | G34: 0 | H34: 18259 | I34: 0 | J34: 226.9654 | K34: 232.2377 | L34: 228.7983 | M34: 130.1928 | N34: 0.560602 | O34: 0 | P34: 0 | Q34: 0 | R34: 5.351227 | S34: 7.837183 | T34: 3.219366 | U34: 4.829101 | V34: 5.351227 | W34: 6.859468 | X34: 9.697403 | Y34: 6.111517 | Z34: 0 | AA34: 4.700865 | AB34: 2.072861 | AC34: 2.559953 | AD34: 4.700865 | AE34: 6.467258 | AF34: 7.243518 | AG34: 12.02307 | AH34: 0 | AI34: 1.944494 | AJ34: 1.674894 | AK34: 0.852062 | AL34: #########
A35: Baby Essentials_Unknown | B35: Baby Food_Unknown | C35: Baby Essentials | D35: Baby Food | E35: Unknown | F35: 115 | G35: 7 | H35: 849 | I35: 849 | J35: 0 | K35: 0 | L35: 0 | M35: 0 | N35: 0 | O35: 0 | P35: 0 | Q35: 0 | R35: 0 | S35: 0 | T35: 0 | U35: 0 | V35: 0 | W35: 0 | X35: 0 | Y35: 0 | Z35: 0 | AA35: 4.700865 | AB35: 2.072861 | AC35: 2.559953 | AD35: 0 | AE35: 0 | AF35: 0 | AG35: 0 | AH35: 0 | AI35: 1.944494 | AJ35: 1.674894 | AK35: 0.852062 | AL35: #########
A36: Baby Essentials_10-15 | B36: Diapers_10-15 | C36: Baby Essentials | D36: Diapers | E36: 46310 | F36: 1 | G36: 0 | H36: 0 | I36: 0 | J36: 0 | K36: 0 | L36: 0 | M36: 0 | N36: 0 | O36: 0 | P36: 0 | Q36: 0 | R36: 0 | S36: 0 | T36: 0 | U36: 0 | V36: 0 | W36: 0 | X36: 0 | Y36: 0 | Z36: 0 | AA36: 1.616149 | AB36: 0.818778 | AC36: 0.043478 | AD36: 4.940896 | AE36: 5.044467 | AF36: 6.358956 | AG36: 5.817529 | AH36: 0 | AI36: 1.944494 | AJ36: 1.674894 | AK36: 0.852062 | AL36: #########
A37: Baby Essentials_20-25 | B37: Diapers_20-25 | C37: Baby Essentials | D37: Diapers | E37: 20-25 | F37: 1 | G37: 0 | H37: 0 | I37: 0 | J37: 0.142857 | K37: 0.043478 | L37: 0.393868 | M37: 0.043478 | N37: 1 | O37: 0.043478 | P37: 0.043478 | Q37: 0.043478 | R37: 0.043478 | S37: 0.043478 | T37: 0.043478 | U37: 0.043478 | V37: 0.043478 | W37: 0.043478 | X37: 0.043478 | Y37: 0.043478 | Z37: 0 | AA37: 1.616149 | AB37: 0.818778 | AC37: 0.043478 | AD37: 0.604598 | AE37: 1.075268 | AF37: 2.905084 | AG37: 1.036618 | AH37: 0 | AI37: 1.944494 | AJ37: 1.674894 | AK37: 0.852062 | AL37: #########
A38: Baby Essentials_25+ | B38: Diapers_25+ | C38: Baby Essentials | D38: Diapers | E38: 25+ | F38: 58 | G38: 1 | H38: 14295 | I38: 38 | J38: 95.22271 | K38: 98.20989 | L38: 93.58637 | M38: 62.78343 | N38: 0.639278 | O38: 0 | P38: 0 | Q38: 0.039416 | R38: 0.962324 | S38: 1.970503 | T38: 0.518687 | U38: 0.755759 | V38: 0.990988 | W38: 1.676232 | X38: 2.811014 | Y38: 1.693274 | Z38: 0 | AA38: 1.616149 | AB38: 0.818778 | AC38: 0.043478 | AD38: 0.819971 | AE38: 1.223488 | AF38: 1.50437 | AG38: 1.524539 | AH38: 0 | AI38: 1.944494 | AJ38: 1.674894 | AK38: 0.852062 | AL38: #########
A39: Baby Essentials_Unknown | B39: Diapers_Unknown | C39: Baby Essentials | D39: Diapers | E39: Unknown | F39: 60 | G39: 8 | H39: 190 | I39: 190 | J39: 0 | K39: 0 | L39: 0 | M39: 0 | N39: 0 | O39: 0 | P39: 0 | Q39: 0 | R39: 0 | S39: 0 | T39: 0 | U39: 0 | V39: 0 | W39: 0 | X39: 0 | Y39: 0 | Z39: 0 | AA39: 1.616149 | AB39: 0.818778 | AC39: 0.043478 | AD39: 0 | AE39: 0 | AF39: 0 | AG39: 0 | AH39: 0 | AI39: 1.944494 | AJ39: 1.674894 | AK39: 0.852062 | AL39: #########
A40: Baby Essentials_10-15 | B40: Milk Formula_10-15 | C40: Baby Essentials | D40: Milk Formula | E40: 46310 | F40: 3 | G40: 0 | H40: 4233 | I40: 0 | J40: 50.95109 | K40: 46.51485 | L40: 44.6565 | M40: 24.61995 | N40: 0.529292 | O40: 5.741263 | P40: 5.741263 | Q40: 5.741263 | R40: 16.15364 | S40: 24.61995 | T40: 5.741263 | U40: 5.741263 | V40: 5.741263 | W40: 16.15364 | X40: 24.61995 | Y40: 15.50495 | Z40: 0 | AA40: 1.652932 | AB40: 0.962042 | AC40: 1.524539 | AD40: 4.940896 | AE40: 5.044467 | AF40: 6.358956 | AG40: 5.817529 | AH40: 0 | AI40: 1.944494 | AJ40: 1.674894 | AK40: 0.852062 | AL40: #########
...

Sheet Copy of Refrence Data
A1: Category_ASP Key | B1: Subcat_ASP Key | C1: Parent Category | D1: Sub Category | E1: ASP Bucket | F1: Count of SKUs (Onhand >0) | G1: Count of Non-Moving SKUs | H1: Total Onhand | I1: Non-Moving Onhand | J1: Total ROS (L14D) | K1: Total ROS (L30D) | L1: Total ROS (L60D) | M1: ROS of Top 20% SKUs | N1: Concentration Index | O1: P10 ROS (All) | P1: P20 ROS (All) | Q1: P30 ROS (All) | R1: P50 ROS (All) | S1: P70 ROS (All) | T1: P10 ROS (Moving) | U1: P20 ROS (Moving) | V1: P30 ROS (Moving) | W1: P50 ROS (Moving) | X1: P70 ROS (Moving) | Y1: SKU Efficiency | Z1: Run Date
A2: _10-15 | B2: _10-15 | E2: 46310 | F2: 4 | G2: 0 | H2: 2036 | I2: 0 | J2: 0.267857 | K2: 0.085145 | L2: 0.051957 | M2: 0.085145 | N2: 1 | O2: 0.085145 | P2: 0.085145 | Q2: 0.085145 | R2: 0.085145 | S2: 0.085145 | T2: 0.085145 | U2: 0.085145 | V2: 0.085145 | W2: 0.085145 | X2: 0.085145 | Y2: 0.085145 | Z2: #########
A3: _15-20 | B3: _15-20 | E3: 15-20 | F3: 2 | G3: 0 | H3: 2726 | I3: 0 | J3: 0 | K3: 0 | L3: 0 | M3: 0 | Z3: #########
A4: _20-25 | B4: _20-25 | E4: 20-25 | F4: 3 | G4: 0 | H4: 655 | I4: 0 | J4: 0.285714 | K4: 0.332258 | L4: 0.386348 | M4: 0.232258 | N4: 0.699029 | O4: 0.1 | P4: 0.1 | Q4: 0.1 | R4: 0.232258 | S4: 0.232258 | T4: 0.1 | U4: 0.1 | V4: 0.1 | W4: 0.232258 | X4: 0.232258 | Y4: 0.166129 | Z4: #########
A5: _25+ | B5: _25+ | E5: 25+ | F5: 42 | G5: 35 | H5: 54538 | I5: 53154 | J5: 0.285714 | K5: 0.3 | L5: 0.352276 | M5: 0.266667 | N5: 0.888889 | O5: 0 | P5: 0 | Q5: 0 | R5: 0.033333 | S5: 0.1 | T5: 0.033333 | U5: 0.033333 | V5: 0.033333 | W5: 0.1 | X5: 0.166667 | Y5: 0.05 | Z5: #########
A6: _5-10 | B6: _5-10 | E6: 46300 | F6: 2 | G6: 0 | H6: 1803 | I6: 0 | J6: 0 | K6: 0 | L6: 0 | M6: 0 | O6: 0 | P6: 0 | Q6: 0 | R6: 0 | S6: 0 | Y6: 0 | Z6: #########
A7: _Unknown | B7: _Unknown | E7: Unknown | F7: 22 | G7: 22 | H7: 160 | I7: 160 | J7: 0 | K7: 0 | L7: 0 | M7: 0 | O7: 0 | P7: 0 | Q7: 0 | R7: 0 | S7: 0 | Y7: 0 | Z7: #########
A8: Adult Care_20-25 | B8: Accessories_20-25 | C8: Adult Care | D8: Accessories | E8: 20-25 | F8: 0 | G8: 0 | H8: 0 | I8: 0 | J8: 0.076923 | K8: 2.034483 | L8: 0.118502 | M8: 2.034483 | N8: 1 | O8: 2.034483 | P8: 2.034483 | Q8: 2.034483 | R8: 2.034483 | S8: 2.034483 | T8: 2.034483 | U8: 2.034483 | V8: 2.034483 | W8: 2.034483 | X8: 2.034483 | Y8: 2.034483 | Z8: #########
A9: Adult Care_25+ | B9: Accessories_25+ | C9: Adult Care | D9: Accessories | E9: 25+ | F9: 6 | G9: 5 | H9: 194 | I9: 184 | J9: 0 | K9: 0 | L9: 0.090909 | M9: 0 | O9: 0 | P9: 0 | Q9: 0 | R9: 0 | S9: 0 | Y9: 0 | Z9: #########
A10: Adult Care_Unknown | B10: Accessories_Unknown | C10: Adult Care | D10: Accessories | E10: Unknown | F10: 3 | G10: 3 | H10: 41 | I10: 41 | J10: 0 | K10: 0 | L10: 0 | M10: 0 | Z10: #########
A11: Adult Care_15-20 | B11: Condoms_15-20 | C11: Adult Care | D11: Condoms | E11: 15-20 | F11: 4 | G11: 0 | H11: 2292 | I11: 0 | J11: 14.95384 | K11: 13.47098 | L11: 14.19314 | M11: 6.131733 | N11: 0.455181 | O11: 2.696133 | P11: 2.696133 | Q11: 2.696133 | R11: 4.643116 | S11: 6.131733 | T11: 2.696133 | U11: 2.696133 | V11: 2.696133 | W11: 4.643116 | X11: 6.131733 | Y11: 4.490327 | Z11: #########
A12: Adult Care_25+ | B12: Condoms_25+ | C12: Adult Care | D12: Condoms | E12: 25+ | F12: 21 | G12: 0 | H12: 8222 | I12: 0 | J12: 80.80433 | K12: 80.62199 | L12: 79.61703 | M12: 36.67825 | N12: 0.454941 | O12: 1.331257 | P12: 1.849147 | Q12: 3.413527 | R12: 4.407286 | S12: 7.620216 | T12: 1.331257 | U12: 1.849147 | V12: 3.413527 | W12: 4.407286 | X12: 7.620216 | Y12: 5.758713 | Z12: #########
A13: Adult Care_5-10 | B13: Condoms_5-10 | C13: Adult Care | D13: Condoms | E13: 46300 | F13: 4 | G13: 0 | H13: 736 | I13: 0 | J13: 5.472222 | K13: 11.17486 | L13: 9.91429 | M13: 11.17486 | N13: 1 | O13: 0 | P13: 0 | Q13: 0 | R13: 11.17486 | S13: 11.17486 | T13: 11.17486 | U13: 11.17486 | V13: 11.17486 | W13: 11.17486 | X13: 11.17486 | Y13: 5.587432 | Z13: #########
A14: Adult Care_Unknown | B14: Condoms_Unknown | C14: Adult Care | D14: Condoms | E14: Unknown | F14: 7 | G14: 7 | H14: 1059 | I14: 1059 | J14: 0 | K14: 0 | L14: 0 | M14: 0 | O14: 0 | P14: 0 | Q14: 0 | R14: 0 | S14: 0 | Y14: 0 | Z14: #########
A15: Adult Care_25+ | B15: Lubricants_25+ | C15: Adult Care | D15: Lubricants | E15: 25+ | F15: 8 | G15: 0 | H15: 3759 | I15: 0 | J15: 34.54381 | K15: 33.63383 | L15: 34.1862 | M15: 20.07087 | N15: 0.596747 | O15: 0 | P15: 0.932258 | Q15: 1.033333 | R15: 3 | S15: 3.6171 | T15: 0.932258 | U15: 1.033333 | V15: 1.768454 | W15: 3.211812 | X15: 3.6171 | Y15: 3.737092 | Z15: #########
A16: Adult Care_Unknown | B16: Lubricants_Unknown | C16: Adult Care | D16: Lubricants | E16: Unknown | F16: 0 | G16: 0 | H16: 0 | I16: 0 | J16: 0 | K16: 0 | L16: 0 | M16: 0 | O16: 0 | P16: 0 | Q16: 0 | R16: 0 | S16: 0 | Y16: 0 | Z16: #########
A17: Baby Essentials_0-5 | B17: Baby Bath & Shower_0-5 | C17: Baby Essentials | D17: Baby Bath & Shower | E17: 0-5 | F17: 1 | G17: 0 | H17: 1064 | I17: 0 | J17: 6.665784 | K17: 6.742408 | L17: 7.155114 | M17: 6.742408 | N17: 1 | O17: 6.742408 | P17: 6.742408 | Q17: 6.742408 | R17: 6.742408 | S17: 6.742408 | T17: 6.742408 | U17: 6.742408 | V17: 6.742408 | W17: 6.742408 | X17: 6.742408 | Y17: 6.742408 | Z17: #########
A18: Baby Essentials_10-15 | B18: Baby Bath & Shower_10-15 | C18: Baby Essentials | D18: Baby Bath & Shower | E18: 46310 | F18: 3 | G18: 0 | H18: 49 | I18: 0 | J18: 0.111111 | K18: 0.04 | L18: 0.0367 | M18: 0.04 | N18: 1 | O18: 0.04 | P18: 0.04 | Q18: 0.04 | R18: 0.04 | S18: 0.04 | T18: 0.04 | U18: 0.04 | V18: 0.04 | W18: 0.04 | X18: 0.04 | Y18: 0.04 | Z18: #########
A19: Baby Essentials_15-20 | B19: Baby Bath & Shower_15-20 | C19: Baby Essentials | D19: Baby Bath & Shower | E19: 15-20 | F19: 8 | G19: 1 | H19: 468 | I19: 20 | J19: 1.598901 | K19: 1.365236 | L19: 1.443151 | M19: 1.365236 | N19: 1 | O19: 1.365236 | P19: 1.365236 | Q19: 1.365236 | R19: 1.365236 | S19: 1.365236 | T19: 1.365236 | U19: 1.365236 | V19: 1.365236 | W19: 1.365236 | X19: 1.365236 | Y19: 1.365236 | Z19: #########
A20: Baby Essentials_20-25 | B20: Baby Bath & Shower_20-25 | C20: Baby Essentials | D20: Baby Bath & Shower | E20: 20-25 | F20: 3 | G20: 1 | H20: 727 | I20: 29 | J20: 3.182418 | K20: 3.270005 | L20: 3.611142 | M20: 3.270005 | N20: 1 | O20: 3.270005 | P20: 3.270005 | Q20: 3.270005 | R20: 3.270005 | S20: 3.270005 | T20: 3.270005 | U20: 3.270005 | V20: 3.270005 | W20: 3.270005 | X20: 3.270005 | Y20: 3.270005 | Z20: #########
A21: Baby Essentials_25+ | B21: Baby Bath & Shower_25+ | C21: Baby Essentials | D21: Baby Bath & Shower | E21: 25+ | F21: 16 | G21: 1 | H21: 949 | I21: 2 | J21: 3.248918 | K21: 2.891034 | L21: 2.930254 | M21: 1.049147 | N21: 0.362897 | O21: 0.466889 | P21: 0.466889 | Q21: 0.467593 | R21: 0.907405 | S21: 0.907405 | T21: 0.466889 | U21: 0.466889 | V21: 0.467593 | W21: 0.907405 | X21: 0.907405 | Y21: 0.722758 | Z21: #########
A22: Baby Essentials_5-10 | B22: Baby Bath & Shower_5-10 | C22: Baby Essentials | D22: Baby Bath & Shower | E22: 46300 | F22: 2 | G22: 0 | H22: 73 | I22: 0 | J22: 0 | K22: 0 | L22: 0 | M22: 0 | Z22: #########
A23: Baby Essentials_Unknown | B23: Baby Bath & Shower_Unknown | C23: Baby Essentials | D23: Baby Bath & Shower | E23: Unknown | F23: 4 | G23: 4 | H23: 200 | I23: 200 | J23: 0 | K23: 0 | L23: 0 | M23: 0 | O23: 0 | P23: 0 | Q23: 0 | R23: 0 | S23: 0 | Y23: 0 | Z23: #########
A24: Baby Essentials_10-15 | B24: Baby Care_10-15 | C24: Baby Essentials | D24: Baby Care | E24: 46310 | F24: 7 | G24: 3 | H24: 335 | I24: 26 | J24: 0.636508 | K24: 0.628758 | L24: 0.525627 | M24: 0.628758 | N24: 1 | O24: 0.628758 | P24: 0.628758 | Q24: 0.628758 | R24: 0.628758 | S24: 0.628758 | T24: 0.628758 | U24: 0.628758 | V24: 0.628758 | W24: 0.628758 | X24: 0.628758 | Y24: 0.628758 | Z24: #########
A25: Baby Essentials_15-20 | B25: Baby Care_15-20 | C25: Baby Essentials | D25: Baby Care | E25: 15-20 | F25: 5 | G25: 0 | H25: 267 | I25: 0 | J25: 0.5 | K25: 0.5 | L25: 0.5 | M25: 0.5 | N25: 1 | O25: 0.5 | P25: 0.5 | Q25: 0.5 | R25: 0.5 | S25: 0.5 | T25: 0.5 | U25: 0.5 | V25: 0.5 | W25: 0.5 | X25: 0.5 | Y25: 0.5 | Z25: #########
A26: Baby Essentials_20-25 | B26: Baby Care_20-25 | C26: Baby Essentials | D26: Baby Care | E26: 20-25 | F26: 1 | G26: 0 | H26: 10 | I26: 0 | J26: 0 | K26: 0 | L26: 0 | M26: 0 | Z26: #########
A27: Baby Essentials_25+ | B27: Baby Care_25+ | C27: Baby Essentials | D27: Baby Care | E27: 25+ | F27: 20 | G27: 2 | H27: 2250 | I27: 15 | J27: 6.876224 | K27: 6.578166 | L27: 7.040684 | M27: 4.007246 | N27: 0.609174 | O27: 0.033333 | P27: 0.066667 | Q27: 0.366667 | R27: 0.907405 | S27: 1.196848 | T27: 0.033333 | U27: 0.066667 | V27: 0.366667 | W27: 0.907405 | X27: 1.196848 | Y27: 0.939738 | Z27: #########
A28: Baby Essentials_5-10 | B28: Baby Care_5-10 | C28: Baby Essentials | D28: Baby Care | E28: 46300 | F28: 1 | G28: 0 | H28: 14 | I28: 0 | J28: 0 | K28: 0 | L28: 0 | M28: 0 | Z28: #########
A29: Baby Essentials_Unknown | B29: Baby Care_Unknown | C29: Baby Essentials | D29: Baby Care | E29: Unknown | F29: 2 | G29: 2 | H29: 46 | I29: 46 | J29: 0 | K29: 0 | L29: 0 | M29: 0 | O29: 0 | P29: 0 | Q29: 0 | R29: 0 | S29: 0 | Y29: 0 | Z29: #########
A30: Baby Essentials_0-5 | B30: Baby Food_0-5 | C30: Baby Essentials | D30: Baby Food | E30: 0-5 | F30: 2 | G30: 0 | H30: 3162 | I30: 0 | J30: 42.18712 | K30: 39.48128 | L30: 39.13113 | M30: 25.49885 | N30: 0.645847 | O30: 13.98243 | P30: 13.98243 | Q30: 13.98243 | R30: 25.49885 | S30: 25.49885 | T30: 13.98243 | U30: 13.98243 | V30: 13.98243 | W30: 25.49885 | X30: 25.49885 | Y30: 19.74064 | Z30: #########
A31: Baby Essentials_10-15 | B31: Baby Food_10-15 | C31: Baby Essentials | D31: Baby Food | E31: 46310 | F31: 21 | G31: 1 | H31: 10138 | I31: 3 | J31: 114.1044 | K31: 113.0732 | L31: 112.7296 | M31: 37.94324 | N31: 0.335563 | O31: 2.113793 | P31: 3.610651 | Q31: 4.940896 | R31: 6.639863 | S31: 8.02561 | T31: 2.113793 | U31: 3.610651 | V31: 4.940896 | W31: 6.639863 | X31: 8.02561 | Y31: 6.281844 | Z31: #########
A32: Baby Essentials_15-20 | B32: Baby Food_15-20 | C32: Baby Essentials | D32: Baby Food | E32: 15-20 | F32: 4 | G32: 0 | H32: 1030 | I32: 0 | J32: 21.28644 | K32: 15.10972 | L32: 13.6056 | M32: 6.754099 | N32: 0.447004 | O32: 1.636508 | P32: 1.636508 | Q32: 3.277122 | R32: 3.441991 | S32: 3.441991 | T32: 1.636508 | U32: 1.636508 | V32: 3.277122 | W32: 3.441991 | X32: 3.441991 | Y32: 3.77743 | Z32: #########
A33: Baby Essentials_20-25 | B33: Baby Food_20-25 | C33: Baby Essentials | D33: Baby Food | E33: 20-25 | F33: 5 | G33: 2 | H33: 289 | I33: 6 | J33: 2.252747 | K33: 1.839733 | L33: 1.715587 | M33: 1.839733 | N33: 1 | O33: 1.839733 | P33: 1.839733 | Q33: 1.839733 | R33: 1.839733 | S33: 1.839733 | T33: 1.839733 | U33: 1.839733 | V33: 1.839733 | W33: 1.839733 | X33: 1.839733 | Y33: 1.839733 | Z33: #########
A34: Baby Essentials_25+ | B34: Baby Food_25+ | C34: Baby Essentials | D34: Baby Food | E34: 25+ | F34: 21 | G34: 0 | H34: 5648 | I34: 0 | J34: 22.55563 | K34: 21.15437 | L34: 21.71342 | M34: 9.819323 | N34: 0.464175 | O34: 0.333333 | P34: 0.595699 | Q34: 0.629032 | R34: 1.393845 | S34: 2.034792 | T34: 0.333333 | U34: 0.595699 | V34: 0.629032 | W34: 1.393845 | X34: 2.034792 | Y34: 1.322148 | Z34: #########
A35: Baby Essentials_5-10 | B35: Baby Food_5-10 | C35: Baby Essentials | D35: Baby Food | E35: 46300 | F35: 25 | G35: 0 | H35: 18050 | I35: 0 | J35: 217.2806 | K35: 206.8136 | L35: 203.2072 | M35: 98.51943 | N35: 0.476368 | O35: 3.219366 | P35: 4.700865 | Q35: 5.250105 | R35: 6.008327 | S35: 10.1361 | T35: 4.665716 | U35: 4.829101 | V35: 5.351227 | W35: 6.467258 | X35: 10.1361 | Y35: 8.991894 | Z35: #########
A36: Baby Essentials_Unknown | B36: Baby Food_Unknown | C36: Baby Essentials | D36: Baby Food | E36: Unknown | F36: 9 | G36: 9 | H36: 629 | I36: 629 | J36: 0 | K36: 0 | L36: 0 | M36: 0 | O36: 0 | P36: 0 | Q36: 0 | R36: 0 | S36: 0 | Y36: 0 | Z36: #########
A37: Baby Essentials_25+ | B37: Diapers_25+ | C37: Baby Essentials | D37: Diapers | E37: 25+ | F37: 71 | G37: 9 | H37: 15186 | I37: 346 | J37: 91.29439 | K37: 88.90458 | L37: 88.45829 | M37: 49.13234 | N37: 0.552641 | O37: 0 | P37: 0.433333 | Q37: 0.868054 | R37: 1.508152 | S37: 2.690655 | T37: 0.60767 | U37: 0.868054 | V37: 1.151269 | W37: 1.775751 | X37: 2.811014 | Y37: 2.222615 | Z37: #########
A38: Baby Essentials_Unknown | B38: Diapers_Unknown | C38: Baby Essentials | D38: Diapers | E38: Unknown | F38: 20 | G38: 20 | H38: 445 | I38: 445 | J38: 0 | K38: 0 | L38: 0 | M38: 0 | O38: 0 | P38: 0 | Q38: 0 | R38: 0 | S38: 0 | Y38: 0 | Z38: #########
A39: Baby Essentials_10-15 | B39: Milk Formula_10-15 | C39: Baby Essentials | D39: Milk Formula | E39: 46310 | F39: 3 | G39: 0 | H39: 4233 | I39: 0 | J39: 50.95109 | K39: 46.51485 | L39: 44.6565 | M39: 24.61995 | N39: 0.529292 | O39: 5.741263 | P39: 5.741263 | Q39: 5.741263 | R39: 16.15364 | S39: 24.61995 | T39: 5.741263 | U39: 5.741263 | V39: 5.741263 | W39: 16.15364 | X39: 24.61995 | Y39: 15.50495 | Z39: #########
A40: Baby Essentials_25+ | B40: Milk Formula_25+ | C40: Baby Essentials | D40: Milk Formula | E40: 25+ | F40: 67 | G40: 9 | H40: 10508 | I40: 147 | J40: 69.02153 | K40: 69.58987 | L40: 68.57639 | M40: 38.14018 | N40: 0.548071 | O40: 0.133333 | P40: 0.380023 | Q40: 0.608453 | R40: 1.779412 | S40: 2.696333 | T40: 0.3 | U40: 0.527957 | V40: 0.803241 | W40: 1.998299 | X40: 3.046311 | Y40: 2.174683 | Z40: #########
...

Sheet New Launch Success Rate
A1: Subcat_ASP Bucket | B1: Total New Launches (Last 180d) | C1: Successful Launches | D1: Aggregation Level Used | E1: Launch Success Rate | F1: Revised
A2: Accessories_10-15 | B2: 0 | C2: 0 | D2: No Launches in Entire Category | E2: Not Applicable | F2: =if(D2="Fallback: ParentCategory_ASP",E2*0.75, IF(D2="Fallback: ParentCategory",E2*0.5,E2)) -> Not Applicable
A3: Accessories_15-20 | B3: 0 | C3: 0 | D3: No Launches in Entire Category | E3: Not Applicable | F3: =if(D3="Fallback: ParentCategory_ASP",E3*0.75, IF(D3="Fallback: ParentCategory",E3*0.5,E3)) -> Not Applicable
A4: Accessories_20-25 | B4: 3 | C4: 2 | D4: Fallback: ParentCategory | E4: 0.667 | F4: =if(D4="Fallback: ParentCategory_ASP",E4*0.75, IF(D4="Fallback: ParentCategory",E4*0.5,E4)) -> 0.3335
A5: Accessories_25+ | B5: 0 | C5: 0 | D5: No Launches in Entire Category | E5: Not Applicable | F5: =if(D5="Fallback: ParentCategory_ASP",E5*0.75, IF(D5="Fallback: ParentCategory",E5*0.5,E5)) -> Not Applicable
A6: Accessories_25+ | B6: 3 | C6: 2 | D6: Fallback: ParentCategory_ASP | E6: 0.667 | F6: =if(D6="Fallback: ParentCategory_ASP",E6*0.75, IF(D6="Fallback: ParentCategory",E6*0.5,E6)) -> 0.50025
A7: Accessories_Unknown | B7: 0 | C7: 0 | D7: No Launches in Entire Category | E7: Not Applicable | F7: =if(D7="Fallback: ParentCategory_ASP",E7*0.75, IF(D7="Fallback: ParentCategory",E7*0.5,E7)) -> Not Applicable
A8: Accessories_Unknown | B8: 3 | C8: 2 | D8: Fallback: ParentCategory | E8: 0.667 | F8: =if(D8="Fallback: ParentCategory_ASP",E8*0.75, IF(D8="Fallback: ParentCategory",E8*0.5,E8)) -> 0.3335
A9: Activity Books_0-5 | B9: 105 | C9: 61 | D9: Fallback: ParentCategory | E9: 0.581 | F9: =if(D9="Fallback: ParentCategory_ASP",E9*0.75, IF(D9="Fallback: ParentCategory",E9*0.5,E9)) -> 0.2905
A10: Activity Books_10-15 | B10: 4 | C10: 4 | D10: Fallback: ParentCategory_ASP | E10: 1 | F10: =if(D10="Fallback: ParentCategory_ASP",E10*0.75, IF(D10="Fallback: ParentCategory",E10*0.5,E10)) -> 0.75
A11: Activity Books_20-25 | B11: 105 | C11: 61 | D11: Fallback: ParentCategory | E11: 0.581 | F11: =if(D11="Fallback: ParentCategory_ASP",E11*0.75, IF(D11="Fallback: ParentCategory",E11*0.5,E11)) -> 0.2905
A12: Activity Books_25+ | B12: 3 | C12: 0 | D12: Exact Subcat_ASP Match | E12: 0 | F12: =if(D12="Fallback: ParentCategory_ASP",E12*0.75, IF(D12="Fallback: ParentCategory",E12*0.5,E12)) -> 0
A13: Activity Books_5-10 | B13: 3 | C13: 3 | D13: Fallback: ParentCategory_ASP | E13: 1 | F13: =if(D13="Fallback: ParentCategory_ASP",E13*0.75, IF(D13="Fallback: ParentCategory",E13*0.5,E13)) -> 0.75
A14: Adapters_25+ | B14: 12 | C14: 0 | D14: Fallback: ParentCategory_ASP | E14: 0 | F14: =if(D14="Fallback: ParentCategory_ASP",E14*0.75, IF(D14="Fallback: ParentCategory",E14*0.5,E14)) -> 0
A15: Adult Diapers_15-20 | B15: 3 | C15: 3 | D15: Fallback: ParentCategory_ASP | E15: 1 | F15: =if(D15="Fallback: ParentCategory_ASP",E15*0.75, IF(D15="Fallback: ParentCategory",E15*0.5,E15)) -> 0.75
A16: Adult Diapers_20-25 | B16: 6 | C16: 5 | D16: Fallback: ParentCategory_ASP | E16: 0.833 | F16: =if(D16="Fallback: ParentCategory_ASP",E16*0.75, IF(D16="Fallback: ParentCategory",E16*0.5,E16)) -> 0.62475
A17: Adult Diapers_25+ | B17: 49 | C17: 42 | D17: Fallback: ParentCategory_ASP | E17: 0.857 | F17: =if(D17="Fallback: ParentCategory_ASP",E17*0.75, IF(D17="Fallback: ParentCategory",E17*0.5,E17)) -> 0.64275
A18: Adult Diapers_Unknown | B18: 62 | C18: 53 | D18: Fallback: ParentCategory | E18: 0.855 | F18: =if(D18="Fallback: ParentCategory_ASP",E18*0.75, IF(D18="Fallback: ParentCategory",E18*0.5,E18)) -> 0.4275
A19: Air Fryer_25+ | B19: 10 | C19: 7 | D19: Fallback: ParentCategory_ASP | E19: 0.7 | F19: =if(D19="Fallback: ParentCategory_ASP",E19*0.75, IF(D19="Fallback: ParentCategory",E19*0.5,E19)) -> 0.525
... A28: Airpods_25+ | B28: 5 | C28: 0 | D28: Fallback: ParentCategory_ASP | E28: 0 | F28: =if(D28="Fallback: ParentCategory_ASP",E28*0.75, IF(D28="Fallback: ParentCategory",E28*0.5,E28)) -> 0
A29: Android Smartphone_25+ | B29: 0 | C29: 0 | D29: No Launches in Entire Category | E29: Not Applicable | F29: =if(D29="Fallback: ParentCategory_ASP",E29*0.75, IF(D29="Fallback: ParentCategory",E29*0.5,E29)) -> Not Applicable
A30: Android Smartphone_Unknown | B30: 0 | C30: 0 | D30: No Launches in Entire Category | E30: Not Applicable | F30: =if(D30="Fallback: ParentCategory_ASP",E30*0.75, IF(D30="Fallback: ParentCategory",E30*0.5,E30)) -> Not Applicable
A31: Apple Watch_Unknown | B31: 0 | C31: 0 | D31: No Launches in Entire Category | E31: Not Applicable | F31: =if(D31="Fallback: ParentCategory_ASP",E31*0.75, IF(D31="Fallback: ParentCategory",E31*0.5,E31)) -> Not Applicable
A32: Apple iPads_Unknown | B32: 0 | C32: 0 | D32: No Launches in Entire Category | E32: Not Applicable | F32: =if(D32="Fallback: ParentCategory_ASP",E32*0.75, IF(D32="Fallback: ParentCategory",E32*0.5,E32)) -> Not Applicable
A33: Apple_25+ | B33: 0 | C33: 0 | D33: No Launches in Entire Category | E33: Not Applicable | F33: =if(D33="Fallback: ParentCategory_ASP",E33*0.75, IF(D33="Fallback: ParentCategory",E33*0.5,E33)) -> Not Applicable
A34: Apple_Unknown | B34: 0 | C34: 0 | D34: No Launches in Entire Category | E34: Not Applicable | F34: =if(D34="Fallback: ParentCategory_ASP",E34*0.75, IF(D34="Fallback: ParentCategory",E34*0.5,E34)) -> Not Applicable
A35: Appliances_10-15 | B35: 1 | C35: 1 | D35: Fallback: ParentCategory | E35: Not Applicable | F35: =if(D35="Fallback: ParentCategory_ASP",E35*0.75, IF(D35="Fallback: ParentCategory",E35*0.5,E35)) -> #VALUE!
A36: Appliances_20-25 | B36: 1 | C36: 1 | D36: Fallback: ParentCategory | E36: Not Applicable | F36: =if(D36="Fallback: ParentCategory_ASP",E36*0.75, IF(D36="Fallback: ParentCategory",E36*0.5,E36)) -> #VALUE!
A37: Appliances_25+ | B37: 1 | C37: 1 | D37: Fallback: ParentCategory | E37: Not Applicable | F37: =if(D37="Fallback: ParentCategory_ASP",E37*0.75, IF(D37="Fallback: ParentCategory",E37*0.5,E37)) -> #VALUE!
A38: Appliances_Unknown | B38: 1 | C38: 1 | D38: Fallback: ParentCategory | E38: Not Applicable | F38: =if(D38="Fallback: ParentCategory_ASP",E38*0.75, IF(D38="Fallback: ParentCategory",E38*0.5,E38)) -> #VALUE!
