Workbook

Sheet Queries
A1: Data | B1: Queries
A2: Refrence Data | B2: https://careem-insights.careem-engineering.com/sqllab?savedQueryId=432380
A3: New Launch Success | B3: https://careem-insights.careem-engineering.com/sqllab?savedQueryId=432384

Sheet Category Saturation
A1: Key | B1: Concentration Index | C1: SKU Efficiency | D1: W/D | E1: Score
A2: =B2&C2&D2 -> LowHighWidth | B2: Low | C2: High | D2: Width | E2: 100
A3: =B3&C3&D3 -> LowHighDepth | B3: Low | C3: High | D3: Depth | E3: 90
A4: =B4&C4&D4 -> LowLowWidth | B4: Low | C4: Low | D4: Width | E4: 40
A5: =B5&C5&D5 -> LowLowDepth | B5: Low | C5: Low | D5: Depth | E5: 15
A6: =B6&C6&D6 -> MediumHighWidth | B6: Medium | C6: High | D6: Width | E6: 25
A7: =B7&C7&D7 -> MediumHighDepth | B7: Medium | C7: High | D7: Depth | E7: 60
A8: =B8&C8&D8 -> MediumLowWidth | B8: Medium | C8: Low | D8: Width | E8: 25
A9: =B9&C9&D9 -> MediumLowDepth | B9: Medium | C9: Low | D9: Depth | E9: 50
A10: =B10&C10&D10 -> HighHighWidth | B10: High | C10: High | D10: Width | E10: 25
A11: =B11&C11&D11 -> HighHighDepth | B11: High | C11: High | D11: Depth | E11: 0
A12: =B12&C12&D12 -> HighLowWidth | B12: High | C12: Low | D12: Width | E12: 15
A13: =B13&C13&D13 -> HighLowDepth | B13: High | C13: Low | D13: Depth | E13: 0

Sheet Monetization
A1: Types | B1: Score
A2: Promo Calendar Committed | B2: 75
A3: Trade Funding | B3: 100
A4: Ads Support | B4: 100
A5: No Support | B5: 0

Sheet Refrence Data
A1: Category_ASP Key | B1: Subcat_ASP Key | C1: Parent Category | D1: Sub Category | E1: ASP Bucket | F1: Count of SKUs (Avail >50%) | G1: Count of Non-Moving SKUs | H1: Total Onhand | I1: Non-Moving Onhand | J1: Total ROS (L14D) | K1: Total ROS (L30D) | L1: Total ROS (L60D) | M1: ROS of Top 20% SKUs | N1: Concentration Index | O1: P10 ROS (All) | P1: P20 ROS (All) | Q1: P30 ROS (All) | R1: P50 ROS (All) | S1: P70 ROS (All) | T1: P10 ROS (Moving) | U1: P20 ROS (Moving) | V1: P30 ROS (Moving) | W1: P50 ROS (Moving) | X1: P70 ROS (Moving) | Y1: SKU Efficiency | Z1: Sub Category P50 ROS (All) | AA1: Sub Category P50 ROS (Moving) | AB1: Sub Category SKU Efficiency | AC1: Sub Category Median SKU Efficiency | AD1: Category-ASP P50 ROS (All) | AE1: Category-ASP P50 ROS (Moving) | AF1: Category-ASP SKU Efficiency | AG1: Category-ASP Median SKU Efficiency | AH1: Parent Category P50 ROS (All) | AI1: Parent Category P50 ROS (Moving) | AJ1: Parent Category SKU Efficiency | AK1: Parent Category Median SKU Efficiency | AL1: Run Date
A2: _10-15 | B2: _10-15 | E2: 46310 | F2: 1 | G2: 0 | H2: 313 | I2: 0 | J2: 1.714286 | K2: 2.411099 | L2: 3.565624 | M2: 2.411099 | N2: 1 | O2: 2.411099 | P2: 2.411099 | Q2: 2.411099 | R2: 2.411099 | S2: 2.411099 | T2: 2.411099 | U2: 2.411099 | V2: 2.411099 | W2: 2.411099 | X2: 2.411099 | Y2: 2.411099 | Z2: 0 | AA2: 2.411099 | AB2: 0.005492 | AC2: 0 | AD2: 2.411099 | AE2: 2.411099 | AF2: 2.411099 | AG2: 2.411099 | AH2: 0 | AI2: 2.411099 | AJ2: 0.005492 | AK2: 0 | AL2: #########
A3: _25+ | B3: _25+ | E3: 25+ | F3: 60 | G3: 9 | H3: 70485 | I3: 70485 | J3: 0 | K3: 0 | L3: 5.94438 | M3: 0 | N3: 0 | O3: 0 | P3: 0 | Q3: 0 | R3: 0 | S3: 0 | T3: 0 | U3: 0 | V3: 0 | W3: 0 | X3: 0 | Y3: 0 | Z3: 0 | AA3: 2.411099 | AB3: 0.005492 | AC3: 0 | AD3: 0 | AE3: 0 | AF3: 0 | AG3: 0 | AH3: 0 | AI3: 2.411099 | AJ3: 0.005492 | AK3: 0 | AL3: #########
A4: _Unknown | B4: _Unknown | E4: Unknown | F4: 378 | G4: 3 | H4: 203 | I4: 203 | J4: 0 | K4: 0 | L4: 0 | M4: 0 | N4: 0 | O4: 0 | P4: 0 | Q4: 0 | R4: 0 | S4: 0 | T4: 0 | U4: 0 | V4: 0 | W4: 0 | X4: 0 | Y4: 0 | Z4: 0 | AA4: 2.411099 | AB4: 0.005492 | AC4: 0 | AD4: 0 | AE4: 0 | AF4: 0 | AG4: 0 | AH4: 0 | AI4: 2.411099 | AJ4: 0.005492 | AK4: 0 | AL4: #########
A5: Adult Care_25+ | B5: Accessories_25+ | C5: Adult Care | D5: Accessories | E5: 25+ | F5: 1 | G5: 0 | H5: 0 | I5: 0 | J5: 0 | K5: 0.090909 | L5: 1.224026 | M5: 0.090909 | N5: 1 | O5: 0.090909 | P5: 0.090909 | Q5: 0.090909 | R5: 0.090909 | S5: 0.090909 | T5: 0.090909 | U5: 0.090909 | V5: 0.090909 | W5: 0.090909 | X5: 0.090909 | Y5: 0.090909 | Z5: 0 | AA5: 0.090909 | AB5: 0.008354 | AC5: 0 | AD5: 3.468971 | AE5: 3.642425 | AF5: 4.357632 | AG5: 3.886419 | AH5: 1.07037 | AI5: 3.642425 | AJ5: 2.855238 | AK5: 1.930624 | AL5: #########
A6: Adult Care_Unknown | B6: Accessories_Unknown | C6: Adult Care | D6: Accessories | E6: Unknown | F6: 1 | G6: 0 | H6: 0 | I6: 0 | J6: 0 | K6: 0 | L6: 0 | M6: 0 | N6: 0 | O6: 0 | P6: 0 | Q6: 0 | R6: 0 | S6: 0 | T6: 0 | U6: 0 | V6: 0 | W6: 0 | X6: 0 | Y6: 0 | Z6: 0 | AA6: 0.090909 | AB6: 0.008354 | AC6: 0 | AD6: 0 | AE6: 0 | AF6: 0 | AG6: 0 | AH6: 1.07037 | AI6: 3.642425 | AJ6: 2.855238 | AK6: 1.930624 | AL6: #########
A7: Adult Care_15-20 | B7: Condoms_15-20 | C7: Adult Care | D7: Condoms | E7: 15-20 | F7: 3 | G7: 0 | H7: 1448 | I7: 0 | J7: 14.18623 | K7: 14.39415 | L7: 16.0535 | M7: 8.702803 | N7: 0.604607 | O7: 2.053049 | P7: 2.053049 | Q7: 2.053049 | R7: 3.638295 | S7: 8.702803 | T7: 2.053049 | U7: 2.053049 | V7: 2.053049 | W7: 3.638295 | X7: 8.702803 | Y7: 4.798049 | Z7: 1.930624 | AA7: 3.642425 | AB7: 3.209722 | AC7: 4.798049 | AD7: 3.638295 | AE7: 3.638295 | AF7: 4.798049 | AG7: 4.798049 | AH7: 1.07037 | AI7: 3.642425 | AJ7: 2.855238 | AK7: 1.930624 | AL7: #########
A8: Adult Care_20-25 | B8: Condoms_20-25 | C8: Adult Care | D8: Condoms | E8: 20-25 | F8: 1 | G8: 0 | H8: 240 | I8: 0 | J8: 0.942002 | K8: 1.930624 | L8: 2.295348 | M8: 1.930624 | N8: 1 | O8: 1.930624 | P8: 1.930624 | Q8: 1.930624 | R8: 1.930624 | S8: 1.930624 | T8: 1.930624 | U8: 1.930624 | V8: 1.930624 | W8: 1.930624 | X8: 1.930624 | Y8: 1.930624 | Z8: 1.930624 | AA8: 3.642425 | AB8: 3.209722 | AC8: 4.798049 | AD8: 1.930624 | AE8: 1.930624 | AF8: 1.930624 | AG8: 1.930624 | AH8: 1.07037 | AI8: 3.642425 | AJ8: 2.855238 | AK8: 1.930624 | AL8: #########
A9: Adult Care_25+ | B9: Condoms_25+ | C9: Adult Care | D9: Condoms | E9: 25+ | F9: 17 | G9: 0 | H9: 7304 | I9: 0 | J9: 85.28796 | K9: 82.58739 | L9: 83.14779 | M9: 42.78447 | N9: 0.518051 | O9: 0.719298 | P9: 1.239692 | Q9: 2.840741 | R9: 3.642425 | S9: 6.231089 | T9: 0.719298 | U9: 1.239692 | V9: 2.840741 | W9: 3.642425 | X9: 6.231089 | Y9: 4.858082 | Z9: 1.930624 | AA9: 3.642425 | AB9: 3.209722 | AC9: 4.798049 | AD9: 3.468971 | AE9: 3.642425 | AF9: 4.357632 | AG9: 3.886419 | AH9: 1.07037 | AI9: 3.642425 | AJ9: 2.855238 | AK9: 1.930624 | AL9: #########
A10: Adult Care_5-10 | B10: Condoms_5-10 | C10: Adult Care | D10: Condoms | E10: 46300 | F10: 3 | G10: 0 | H10: 708 | I10: 0 | J10: 14.26952 | K10: 23.05727 | L10: 22.40387 | M10: 11.62304 | N10: 0.504094 | O10: 0 | P10: 0 | Q10: 0 | R10: 11.43423 | S10: 11.62304 | T10: 11.43423 | U10: 11.43423 | V10: 11.43423 | W10: 11.62304 | X10: 11.62304 | Y10: 7.685756 | Z10: 1.930624 | AA10: 3.642425 | AB10: 3.209722 | AC10: 4.798049 | AD10: 11.43423 | AE10: 11.62304 | AF10: 7.685756 | AG10: 7.685756 | AH10: 1.07037 | AI10: 3.642425 | AJ10: 2.855238 | AK10: 1.930624 | AL10: #########
A11: Adult Care_Unknown | B11: Condoms_Unknown | C11: Adult Care | D11: Condoms | E11: Unknown | F11: 14 | G11: 0 | H11: 0 | I11: 0 | J11: 0 | K11: 0 | L11: 0 | M11: 0 | N11: 0 | O11: 0 | P11: 0 | Q11: 0 | R11: 0 | S11: 0 | T11: 0 | U11: 0 | V11: 0 | W11: 0 | X11: 0 | Y11: 0 | Z11: 1.930624 | AA11: 3.642425 | AB11: 3.209722 | AC11: 4.798049 | AD11: 0 | AE11: 0 | AF11: 0 | AG11: 0 | AH11: 1.07037 | AI11: 3.642425 | AJ11: 2.855238 | AK11: 1.930624 | AL11: #########
A12: Adult Care_25+ | B12: Lubricants_25+ | C12: Adult Care | D12: Lubricants | E12: 25+ | F12: 9 | G12: 0 | H12: 3301 | I12: 0 | J12: 34.2415 | K12: 34.97777 | L12: 35.86931 | M12: 18.86995 | N12: 0.539484 | O12: 0 | P12: 1.07037 | Q12: 1.08688 | R12: 3.311832 | S12: 5.123815 | T12: 1.07037 | U12: 1.08688 | V12: 1.175944 | W12: 4.338978 | X12: 5.123815 | Y12: 3.886419 | Z12: 1.07037 | AA12: 4.338978 | AB12: 2.331852 | AC12: 3.886419 | AD12: 3.468971 | AE12: 3.642425 | AF12: 4.357632 | AG12: 3.886419 | AH12: 1.07037 | AI12: 3.642425 | AJ12: 2.855238 | AK12: 1.930624 | AL12: #########
A13: Adult Care_Unknown | B13: Lubricants_Unknown | C13: Adult Care | D13: Lubricants | E13: Unknown | F13: 6 | G13: 0 | H13: 0 | I13: 0 | J13: 0 | K13: 0 | L13: 0 | M13: 0 | N13: 0 | O13: 0 | P13: 0 | Q13: 0 | R13: 0 | S13: 0 | T13: 0 | U13: 0 | V13: 0 | W13: 0 | X13: 0 | Y13: 0 | Z13: 1.07037 | AA13: 4.338978 | AB13: 2.331852 | AC13: 3.886419 | AD13: 0 | AE13: 0 | AF13: 0 | AG13: 0 | AH13: 1.07037 | AI13: 3.642425 | AJ13: 2.855238 | AK13: 1.930624 | AL13: #########
A14: Baby Essentials_Unknown | B14: Accessories_Unknown | C14: Baby Essentials | D14: Accessories | E14: Unknown | F14: 1 | G14: 0 | H14: 0 | I14: 0 | J14: 0 | K14: 0 | L14: 0 | M14: 0 | N14: 0 | O14: 0 | P14: 0 | Q14: 0 | R14: 0 | S14: 0 | T14: 0 | U14: 0 | V14: 0 | W14: 0 | X14: 0 | Y14: 0 | Z14: 0 | AA14: 0.090909 | AB14: 0.008354 | AC14: 0 | AD14: 0 | AE14: 0 | AF14: 0 | AG14: 0 | AH14: 0 | AI14: 2.000646 | AJ14: 1.750649 | AK14: 1.176239 | AL14: #########
A15: Baby Essentials_0-5 | B15: Baby Bath & Shower_0-5 | C15: Baby Essentials | D15: Baby Bath & Shower | E15: 0-5 | F15: 1 | G15: 0 | H15: 741 | I15: 0 | J15: 7.526557 | K15: 7.278673 | L15: 6.779705 | M15: 7.278673 | N15: 1 | O15: 7.278673 | P15: 7.278673 | Q15: 7.278673 | R15: 7.278673 | S15: 7.278673 | T15: 7.278673 | U15: 7.278673 | V15: 7.278673 | W15: 7.278673 | X15: 7.278673 | Y15: 7.278673 | Z15: 0.5625 | AA15: 0.8 | AB15: 1.015113 | AC15: 1.233604 | AD15: 7.278673 | AE15: 14.02401 | AF15: 8.942804 | AG15: 7.278673 | AH15: 0 | AI15: 2.000646 | AJ15: 1.750649 | AK15: 1.176239 | AL15: #########
A16: Baby Essentials_10-15 | B16: Baby Bath & Shower_10-15 | C16: Baby Essentials | D16: Baby Bath & Shower | E16: 46310 | F16: 1 | G16: 0 | H16: 62 | I16: 0 | J16: 0.142857 | K16: 0.3 | L16: 1.590049 | M16: 0.3 | N16: 1 | O16: 0.3 | P16: 0.3 | Q16: 0.3 | R16: 0.3 | S16: 0.3 | T16: 0.3 | U16: 0.3 | V16: 0.3 | W16: 0.3 | X16: 0.3 | Y16: 0.3 | Z16: 0.5625 | AA16: 0.8 | AB16: 1.015113 | AC16: 1.233604 | AD16: 5.68751 | AE16: 5.969778 | AF16: 7.293228 | AG16: 5.880765 | AH16: 0 | AI16: 2.000646 | AJ16: 1.750649 | AK16: 1.176239 | AL16: #########
A17: Baby Essentials_15-20 | B17: Baby Bath & Shower_15-20 | C17: Baby Essentials | D17: Baby Bath & Shower | E17: 15-20 | F17: 1 | G17: 0 | H17: 145 | I17: 0 | J17: 1.741758 | K17: 1.448531 | L17: 0.974725 | M17: 1.448531 | N17: 1 | O17: 1.448531 | P17: 1.448531 | Q17: 1.448531 | R17: 1.448531 | S17: 1.448531 | T17: 1.448531 | U17: 1.448531 | V17: 1.448531 | W17: 1.448531 | X17: 1.448531 | Y17: 1.448531 | Z17: 0.5625 | AA17: 0.8 | AB17: 1.015113 | AC17: 1.233604 | AD17: 1.448531 | AE17: 2.079566 | AF17: 2.483674 | AG17: 1.448531 | AH17: 0 | AI17: 2.000646 | AJ17: 1.750649 | AK17: 1.176239 | AL17: #########
A18: Baby Essentials_20-25 | B18: Baby Bath & Shower_20-25 | C18: Baby Essentials | D18: Baby Bath & Shower | E18: 20-25 | F18: 5 | G18: 0 | H18: 1064 | I18: 0 | J18: 5.514694 | K18: 6.168019 | L18: 5.518767 | M18: 3.730402 | N18: 0.604797 | O18: 0.485354 | P18: 0.5625 | Q18: 0.5625 | R18: 0.615954 | S18: 0.77381 | T18: 0.485354 | U18: 0.5625 | V18: 0.5625 | W18: 0.615954 | X18: 0.77381 | Y18: 1.233604 | Z18: 0.5625 | AA18: 0.8 | AB18: 1.015113 | AC18: 1.233604 | AD18: 0.862399 | AE18: 1.021927 | AF18: 3.161272 | AG18: 1.233604 | AH18: 0 | AI18: 2.000646 | AJ18: 1.750649 | AK18: 1.176239 | AL18: #########
A19: Baby Essentials_25+ | B19: Baby Bath & Shower_25+ | C19: Baby Essentials | D19: Baby Bath & Shower | E19: 25+ | F19: 4 | G19: 0 | H19: 735 | I19: 0 | J19: 4.253247 | K19: 3.076815 | L19: 2.673457 | M19: 1.031454 | N19: 0.335234 | O19: 0.430546 | P19: 0.430546 | Q19: 0.8 | R19: 0.814815 | S19: 0.814815 | T19: 0.430546 | U19: 0.430546 | V19: 0.8 | W19: 0.814815 | X19: 0.814815 | Y19: 0.769204 | Z19: 0.5625 | AA19: 0.8 | AB19: 1.015113 | AC19: 1.233604 | AD19: 0.853081 | AE19: 1.311011 | AF19: 1.546484 | AG19: 1.427557 | AH19: 0 | AI19: 2.000646 | AJ19: 1.750649 | AK19: 1.176239 | AL19: #########
A20: Baby Essentials_Unknown | B20: Baby Bath & Shower_Unknown | C20: Baby Essentials | D20: Baby Bath & Shower | E20: Unknown | F20: 6 | G20: 1 | H20: 8 | I20: 8 | J20: 0 | K20: 0 | L20: 0 | M20: 0 | N20: 0 | O20: 0 | P20: 0 | Q20: 0 | R20: 0 | S20: 0 | T20: 0 | U20: 0 | V20: 0 | W20: 0 | X20: 0 | Y20: 0 | Z20: 0.5625 | AA20: 0.8 | AB20: 1.015113 | AC20: 1.233604 | AD20: 0 | AE20: 0 | AF20: 0 | AG20: 0 | AH20: 0 | AI20: 2.000646 | AJ20: 1.750649 | AK20: 1.176239 | AL20: #########
A21: Baby Essentials_10-15 | B21: Baby Care_10-15 | C21: Baby Essentials | D21: Baby Care | E21: 46310 | F21: 2 | G21: 0 | H21: 114 | I21: 0 | J21: 0.142857 | K21: 0.280952 | L21: 0.165122 | M21: 0.142857 | N21: 0.508475 | O21: 0.138095 | P21: 0.138095 | Q21: 0.138095 | R21: 0.142857 | S21: 0.142857 | T21: 0.138095 | U21: 0.138095 | V21: 0.138095 | W21: 0.142857 | X21: 0.142857 | Y21: 0.140476 | Z21: 0 | AA21: 0.903704 | AB21: 0.46518 | AC21: 0.97936 | AD21: 5.68751 | AE21: 5.969778 | AF21: 7.293228 | AG21: 5.880765 | AH21: 0 | AI21: 2.000646 | AJ21: 1.750649 | AK21: 1.176239 | AL21: #########
A22: Baby Essentials_15-20 | B22: Baby Care_15-20 | C22: Baby Essentials | D22: Baby Care | E22: 15-20 | F22: 4 | G22: 0 | H22: 386 | I22: 0 | J22: 5.745127 | K22: 4.270427 | L22: 3.61389 | M22: 2.476616 | N22: 0.579946 | O22: 0 | P22: 0 | Q22: 0.620453 | R22: 1.173358 | S22: 1.173358 | T22: 0.620453 | U22: 0.620453 | V22: 0.620453 | W22: 1.173358 | X22: 2.476616 | Y22: 1.067607 | Z22: 0 | AA22: 0.903704 | AB22: 0.46518 | AC22: 0.97936 | AD22: 1.448531 | AE22: 2.079566 | AF22: 2.483674 | AG22: 1.448531 | AH22: 0 | AI22: 2.000646 | AJ22: 1.750649 | AK22: 1.176239 | AL22: #########
A23: Baby Essentials_20-25 | B23: Baby Care_20-25 | C23: Baby Essentials | D23: Baby Care | E23: 20-25 | F23: 2 | G23: 0 | H23: 211 | I23: 0 | J23: 2.229762 | K23: 2.352479 | L23: 2.353423 | M23: 1.508899 | N23: 0.641408 | O23: 0.84358 | P23: 0.84358 | Q23: 0.84358 | R23: 1.508899 | S23: 1.508899 | T23: 0.84358 | U23: 0.84358 | V23: 0.84358 | W23: 1.508899 | X23: 1.508899 | Y23: 1.176239 | Z23: 0 | AA23: 0.903704 | AB23: 0.46518 | AC23: 0.97936 | AD23: 0.862399 | AE23: 1.021927 | AF23: 3.161272 | AG23: 1.233604 | AH23: 0 | AI23: 2.000646 | AJ23: 1.750649 | AK23: 1.176239 | AL23: #########
A24: Baby Essentials_25+ | B24: Baby Care_25+ | C24: Baby Essentials | D24: Baby Care | E24: 25+ | F24: 11 | G24: 0 | H24: 1479 | I24: 0 | J24: 10.61273 | K24: 10.77296 | L24: 10.4052 | M24: 7.121521 | N24: 0.661055 | O24: 0 | P24: 0.033333 | Q24: 0.209179 | R24: 0.738833 | S24: 1.073007 | T24: 0.033333 | U24: 0.209179 | V24: 0.693386 | W24: 0.903704 | X24: 1.818303 | Y24: 0.97936 | Z24: 0 | AA24: 0.903704 | AB24: 0.46518 | AC24: 0.97936 | AD24: 0.853081 | AE24: 1.311011 | AF24: 1.546484 | AG24: 1.427557 | AH24: 0 | AI24: 2.000646 | AJ24: 1.750649 | AK24: 1.176239 | AL24: #########
A25: Baby Essentials_Unknown | B25: Baby Care_Unknown | C25: Baby Essentials | D25: Baby Care | E25: Unknown | F25: 19 | G25: 3 | H25: 60 | I25: 60 | J25: 0 | K25: 0 | L25: 0 | M25: 0 | N25: 0 | O25: 0 | P25: 0 | Q25: 0 | R25: 0 | S25: 0 | T25: 0 | U25: 0 | V25: 0 | W25: 0 | X25: 0 | Y25: 0 | Z25: 0 | AA25: 0.903704 | AB25: 0.46518 | AC25: 0.97936 | AD25: 0 | AE25: 0 | AF25: 0 | AG25: 0 | AH25: 0 | AI25: 2.000646 | AJ25: 1.750649 | AK25: 1.176239 | AL25: #########
A26: Baby Essentials_0-5 | B26: Baby Food_0-5 | C26: Baby Essentials | D26: Baby Food | E26: 0-5 | F26: 2 | G26: 0 | H26: 3071 | I26: 0 | J26: 37.47169 | K26: 37.43535 | L26: 35.96864 | M26: 23.41134 | N26: 0.625381 | O26: 14.02401 | P26: 14.02401 | Q26: 14.02401 | R26: 23.41134 | S26: 23.41134 | T26: 14.02401 | U26: 14.02401 | V26: 14.02401 | W26: 23.41134 | X26: 23.41134 | Y26: 18.71767 | Z26: 0 | AA26: 3.982691 | AB26: 2.175607 | AC26: 2.798774 | AD26: 7.278673 | AE26: 14.02401 | AF26: 8.942804 | AG26: 7.278673 | AH26: 0 | AI26: 2.000646 | AJ26: 1.750649 | AK26: 1.176239 | AL26: #########
A27: Baby Essentials_10-15 | B27: Baby Food_10-15 | C27: Baby Essentials | D27: Baby Food | E27: 46310 | F27: 14 | G27: 0 | H27: 5234 | I27: 0 | J27: 92.23222 | K27: 82.33071 | L27: 71.12986 | M27: 30.00458 | N27: 0.36444 | O27: 1.762662 | P27: 2.827753 | Q27: 3.927619 | R27: 6.297776 | S27: 7.712648 | T27: 2.827753 | U27: 3.582619 | V27: 3.927619 | W27: 6.297776 | X27: 8.039877 | Y27: 5.880765 | Z27: 0 | AA27: 3.982691 | AB27: 2.175607 | AC27: 2.798774 | AD27: 5.68751 | AE27: 5.969778 | AF27: 7.293228 | AG27: 5.880765 | AH27: 0 | AI27: 2.000646 | AJ27: 1.750649 | AK27: 1.176239 | AL27: #########
A28: Baby Essentials_15-20 | B28: Baby Food_15-20 | C28: Baby Essentials | D28: Baby Food | E28: 15-20 | F28: 6 | G28: 0 | H28: 1723 | I28: 0 | J28: 17.45596 | K28: 16.79265 | L28: 15.0443 | M28: 11.61817 | N28: 0.691861 | O28: 0 | P28: 1.021693 | Q28: 1.021693 | R28: 2.079566 | S28: 3.803008 | T28: 1.021693 | U28: 2.073216 | V28: 2.073216 | W28: 2.079566 | X28: 3.803008 | Y28: 2.798774 | Z28: 0 | AA28: 3.982691 | AB28: 2.175607 | AC28: 2.798774 | AD28: 1.448531 | AE28: 2.079566 | AF28: 2.483674 | AG28: 1.448531 | AH28: 0 | AI28: 2.000646 | AJ28: 1.750649 | AK28: 1.176239 | AL28: #########
A29: Baby Essentials_20-25 | B29: Baby Food_20-25 | C29: Baby Essentials | D29: Baby Food | E29: 20-25 | F29: 6 | G29: 0 | H29: 756 | I29: 0 | J29: 4.264444 | K29: 4.127548 | L29: 3.918131 | M29: 2.616207 | N29: 0.63384 | O29: 0 | P29: 0.072751 | Q29: 0.072751 | R29: 0.862399 | S29: 1.021927 | T29: 0.072751 | U29: 0.57619 | V29: 0.57619 | W29: 0.862399 | X29: 1.021927 | Y29: 0.687925 | Z29: 0 | AA29: 3.982691 | AB29: 2.175607 | AC29: 2.798774 | AD29: 0.862399 | AE29: 1.021927 | AF29: 3.161272 | AG29: 1.233604 | AH29: 0 | AI29: 2.000646 | AJ29: 1.750649 | AK29: 1.176239 | AL29: #########
A30: Baby Essentials_25+ | B30: Baby Food_25+ | C30: Baby Essentials | D30: Baby Food | E30: 25+ | F30: 22 | G30: 0 | H30: 4393 | I30: 0 | J30: 24.50624 | K30: 25.63285 | L30: 25.60343 | M30: 10.47688 | N30: 0.408729 | O30: 0.291314 | P30: 0.537959 | Q30: 0.682202 | R30: 1.252657 | S30: 1.543439 | T30: 0.44359 | U30: 0.616667 | V30: 0.772414 | W30: 1.252657 | X30: 1.543439 | Y30: 1.16513 | Z30: 0 | AA30: 3.982691 | AB30: 2.175607 | AC30: 2.798774 | AD30: 0.853081 | AE30: 1.311011 | AF30: 1.546484 | AG30: 1.427557 | AH30: 0 | AI30: 2.000646 | AJ30: 1.750649 | AK30: 1.176239 | AL30: #########
A31: Baby Essentials_5-10 | B31: Baby Food_5-10 | C31: Baby Essentials | D31: Baby Food | E31: 46300 | F31: 44 | G31: 0 | H31: 18270 | I31: 0 | J31: 245.2654 | K31: 268.8022 | L31: 241.6168 | M31: 132.9624 | N31: 0.494648 | O31: 0 | P31: 0.1 | Q31: 3.308682 | R31: 5.168931 | S31: 7.536093 | T31: 2.239556 | U31: 3.982691 | V31: 4.684542 | W31: 6.065433 | X31: 8.372108 | Y31: 6.109142 | Z31: 0 | AA31: 3.982691 | AB31: 2.175607 | AC31: 2.798774 | AD31: 4.766189 | AE31: 6.065433 | AF31: 7.283375 | AG31: 14.66427 | AH31: 0 | AI31: 2.000646 | AJ31: 1.750649 | AK31: 1.176239 | AL31: #########
A32: Baby Essentials_Unknown | B32: Baby Food_Unknown | C32: Baby Essentials | D32: Baby Food | E32: Unknown | F32: 106 | G32: 4 | H32: 249 | I32: 249 | J32: 0 | K32: 0 | L32: 0 | M32: 0 | N32: 0 | O32: 0 | P32: 0 | Q32: 0 | R32: 0 | S32: 0 | T32: 0 | U32: 0 | V32: 0 | W32: 0 | X32: 0 | Y32: 0 | Z32: 0 | AA32: 3.982691 | AB32: 2.175607 | AC32: 2.798774 | AD32: 0 | AE32: 0 | AF32: 0 | AG32: 0 | AH32: 0 | AI32: 2.000646 | AJ32: 1.750649 | AK32: 1.176239 | AL32: #########
A33: Baby Essentials_15-20 | B33: Diapers_15-20 | C33: Baby Essentials | D33: Diapers | E33: 15-20 | F33: 1 | G33: 0 | H33: 0 | I33: 0 | J33: 0 | K33: 0 | L33: 0 | M33: 0 | N33: 0 | O33: 0 | P33: 0 | Q33: 0 | R33: 0 | S33: 0 | T33: 0 | U33: 0 | V33: 0 | W33: 0 | X33: 0 | Y33: 0 | Z33: 0 | AA33: 1.385881 | AB33: 0.789301 | AC33: 0 | AD33: 1.448531 | AE33: 2.079566 | AF33: 2.483674 | AG33: 1.448531 | AH33: 0 | AI33: 2.000646 | AJ33: 1.750649 | AK33: 1.176239 | AL33: #########
A34: Baby Essentials_25+ | B34: Diapers_25+ | C34: Baby Essentials | D34: Diapers | E34: 25+ | F34: 64 | G34: 2 | H34: 9783 | I34: 52 | J34: 104.2218 | K34: 93.92677 | L34: 90.98409 | M34: 61.11327 | N34: 0.650648 | O34: 0 | P34: 0 | Q34: 0 | R34: 0.76737 | S34: 1.791661 | T34: 0.295833 | U34: 0.583333 | V34: 0.830997 | W34: 1.465565 | X34: 2.515914 | Y34: 1.467606 | Z34: 0 | AA34: 1.385881 | AB34: 0.789301 | AC34: 0 | AD34: 0.853081 | AE34: 1.311011 | AF34: 1.546484 | AG34: 1.427557 | AH34: 0 | AI34: 2.000646 | AJ34: 1.750649 | AK34: 1.176239 | AL34: #########
A35: Baby Essentials_Unknown | B35: Diapers_Unknown | C35: Baby Essentials | D35: Diapers | E35: Unknown | F35: 54 | G35: 7 | H35: 221 | I35: 221 | J35: 0 | K35: 0 | L35: 0 | M35: 0 | N35: 0 | O35: 0 | P35: 0 | Q35: 0 | R35: 0 | S35: 0 | T35: 0 | U35: 0 | V35: 0 | W35: 0 | X35: 0 | Y35: 0 | Z35: 0 | AA35: 1.385881 | AB35: 0.789301 | AC35: 0 | AD35: 0 | AE35: 0 | AF35: 0 | AG35: 0 | AH35: 0 | AI35: 2.000646 | AJ35: 1.750649 | AK35: 1.176239 | AL35: #########
A36: Baby Essentials_10-15 | B36: Milk Formula_10-15 | C36: Baby Essentials | D36: Milk Formula | E36: 46310 | F36: 3 | G36: 0 | H36: 3038 | I36: 0 | J36: 49.38564 | K36: 43.57311 | L36: 39.18819 | M36: 21.36145 | N36: 0.490244 | O36: 5.68751 | P36: 5.68751 | Q36: 5.68751 | R36: 16.52414 | S36: 21.36145 | T36: 5.68751 | U36: 5.68751 | V36: 5.68751 | W36: 16.52414 | X36: 21.36145 | Y36: 14.52437 | Z36: 0 | AA36: 1.564856 | AB36: 0.922954 | AC36: 1.427557 | AD36: 5.68751 | AE36: 5.969778 | AF36: 7.293228 | AG36: 5.880765 | AH36: 0 | AI36: 2.000646 | AJ36: 1.750649 | AK36: 1.176239 | AL36: #########
A37: Baby Essentials_25+ | B37: Milk Formula_25+ | C37: Baby Essentials | D37: Milk Formula | E37: 25+ | F37: 49 | G37: 1 | H37: 9495 | I37: 24 | J37: 71.12905 | K37: 69.9503 | L37: 70.72053 | M37: 43.81156 | N37: 0.626324 | O37: 0 | P37: 0 | Q37: 0.066913 | R37: 0.741431 | S37: 1.817111 | T37: 0.074176 | U37: 0.341799 | V37: 0.60989 | W37: 1.460673 | X37: 2.042106 | Y37: 1.427557 | Z37: 0 | AA37: 1.564856 | AB37: 0.922954 | AC37: 1.427557 | AD37: 0.853081 | AE37: 1.311011 | AF37: 1.546484 | AG37: 1.427557 | AH37: 0 | AI37: 2.000646 | AJ37: 1.750649 | AK37: 1.176239 | AL37: #########
A38: Baby Essentials_Unknown | B38: Milk Formula_Unknown | C38: Baby Essentials | D38: Milk Formula | E38: Unknown | F38: 71 | G38: 9 | H38: 279 | I38: 279 | J38: 0 | K38: 0 | L38: 0 | M38: 0 | N38: 0 | O38: 0 | P38: 0 | Q38: 0 | R38: 0 | S38: 0 | T38: 0 | U38: 0 | V38: 0 | W38: 0 | X38: 0 | Y38: 0 | Z38: 0 | AA38: 1.564856 | AB38: 0.922954 | AC38: 1.427557 | AD38: 0 | AE38: 0 | AF38: 0 | AG38: 0 | AH38: 0 | AI38: 2.000646 | AJ38: 1.750649 | AK38: 1.176239 | AL38: #########
A39: Baby Essentials_0-5 | B39: Wipes_0-5 | C39: Baby Essentials | D39: Wipes | E39: 0-5 | F39: 2 | G39: 0 | H39: 0 | I39: 0 | J39: 0 | K39: 0 | L39: 0 | M39: 0 | N39: 0 | O39: 0 | P39: 0 | Q39: 0 | R39: 0 | S39: 0 | T39: 0 | U39: 0 | V39: 0 | W39: 0 | X39: 0 | Y39: 0 | Z39: 0 | AA39: 5.476062 | AB39: 4.026949 | AC39: 0 | AD39: 7.278673 | AE39: 14.02401 | AF39: 8.942804 | AG39: 7.278673 | AH39: 0 | AI39: 2.000646 | AJ39: 1.750649 | AK39: 1.176239 | AL39: #########
A40: Baby Essentials_10-15 | B40: Wipes_10-15 | C40: Baby Essentials | D40: Wipes | E40: 46310 | F40: 6 | G40: 0 | H40: 2153 | I40: 0 | J40: 75.52008 | K40: 63.13917 | L40: 58.41292 | M40: 52.73962 | N40: 0.835292 | O40: 0 | P40: 1.260749 | Q40: 1.260749 | R40: 5.476062 | S40: 13.82796 | T40: 1.260749 | U40: 3.662734 | V40: 3.662734 | W40: 5.476062 | X40: 13.82796 | Y40: 10.52319 | Z40: 0 | AA40: 5.476062 | AB40: 4.026949 | AC40: 0 | AD40: 5.68751 | AE40: 5.969778 | AF40: 7.293228 | AG40: 5.880765 | AH40: 0 | AI40: 2.000646 | AJ40: 1.750649 | AK40: 1.176239 | AL40: #########
...

Sheet Copy of Refrence Data
A1: Category_ASP Key | B1: Subcat_ASP Key | C1: Parent Category | D1: Sub Category | E1: ASP Bucket | F1: Count of SKUs (Onhand >0) | G1: Count of Non-Moving SKUs | H1: Total Onhand | I1: Non-Moving Onhand | J1: Total ROS (L14D) | K1: Total ROS (L30D) | L1: Total ROS (L60D) | M1: ROS of Top 20% SKUs | N1: Concentration Index | O1: P10 ROS (All) | P1: P20 ROS (All) | Q1: P30 ROS (All) | R1: P50 ROS (All) | S1: P70 ROS (All) | T1: P10 ROS (Moving) | U1: P20 ROS (Moving) | V1: P30 ROS (Moving) | W1: P50 ROS (Moving) | X1: P70 ROS (Moving) | Y1: SKU Efficiency | Z1: Sub Category P50 ROS (All) | AA1: Sub Category P50 ROS (Moving) | AB1: Sub Category SKU Efficiency | AC1: Sub Category Median SKU Efficiency | AD1: Category-ASP P50 ROS (All) | AE1: Category-ASP P50 ROS (Moving) | AF1: Category-ASP SKU Efficiency | AG1: Category-ASP Median SKU Efficiency | AH1: Parent Category P50 ROS (All) | AI1: Parent Category P50 ROS (Moving) | AJ1: Parent Category SKU Efficiency | AK1: Parent Category Median SKU Efficiency | AL1: Run Date
A2: _10-15 | B2: _10-15 | E2: 46310 | F2: 7 | G2: 0 | H2: 2231 | I2: 0 | J2: 1.714286 | K2: 2.411099 | L2: 3.565624 | M2: 2.411099 | N2: 1 | O2: 2.411099 | P2: 2.411099 | Q2: 2.411099 | R2: 2.411099 | S2: 2.411099 | T2: 2.411099 | U2: 2.411099 | V2: 2.411099 | W2: 2.411099 | X2: 2.411099 | Y2: 2.411099 | Z2: 0 | AA2: 2.411099 | AB2: 0.077777 | AC2: 0 | AD2: 2.411099 | AE2: 2.411099 | AF2: 2.411099 | AG2: 2.411099 | AH2: 0 | AI2: 2.411099 | AJ2: 0.077777 | AK2: 0 | AL2: #########
A3: _15-20 | B3: _15-20 | E3: 15-20 | F3: 6 | G3: 0 | H3: 1884 | I3: 0 | J3: 0 | K3: 0 | L3: 0 | M3: 0 | N3: 0 | O3: 0 | P3: 0 | Q3: 0 | R3: 0 | S3: 0 | T3: 0 | U3: 0 | V3: 0 | W3: 0 | X3: 0 | Y3: 0 | Z3: 0 | AA3: 2.411099 | AB3: 0.077777 | AC3: 0 | AD3: 0 | AE3: 0 | AF3: 0 | AG3: 0 | AH3: 0 | AI3: 2.411099 | AJ3: 0.077777 | AK3: 0 | AL3: #########
A4: _20-25 | B4: _20-25 | E4: 20-25 | F4: 4 | G4: 0 | H4: 717 | I4: 0 | J4: 0 | K4: 0 | L4: 0 | M4: 0 | N4: 0 | O4: 0 | P4: 0 | Q4: 0 | R4: 0 | S4: 0 | T4: 0 | U4: 0 | V4: 0 | W4: 0 | X4: 0 | Y4: 0 | Z4: 0 | AA4: 2.411099 | AB4: 0.077777 | AC4: 0 | AD4: 0 | AE4: 0 | AF4: 0 | AG4: 0 | AH4: 0 | AI4: 2.411099 | AJ4: 0.077777 | AK4: 0 | AL4: #########
A5: _25+ | B5: _25+ | E5: 25+ | F5: 45 | G5: 36 | H5: 72830 | I5: 71894 | J5: 0 | K5: 0 | L5: 0 | M5: 0 | N5: 0 | O5: 0 | P5: 0 | Q5: 0 | R5: 0 | S5: 0 | T5: 0 | U5: 0 | V5: 0 | W5: 0 | X5: 0 | Y5: 0 | Z5: 0 | AA5: 2.411099 | AB5: 0.077777 | AC5: 0 | AD5: 0 | AE5: 0 | AF5: 0 | AG5: 0 | AH5: 0 | AI5: 2.411099 | AJ5: 0.077777 | AK5: 0 | AL5: #########
A6: _5-10 | B6: _5-10 | E6: 46300 | F6: 2 | G6: 0 | H6: 1416 | I6: 0 | J6: 0 | K6: 0 | L6: 0 | M6: 0 | N6: 0 | O6: 0 | P6: 0 | Q6: 0 | R6: 0 | S6: 0 | T6: 0 | U6: 0 | V6: 0 | W6: 0 | X6: 0 | Y6: 0 | Z6: 0 | AA6: 2.411099 | AB6: 0.077777 | AC6: 0 | AD6: 0 | AE6: 0 | AF6: 0 | AG6: 0 | AH6: 0 | AI6: 2.411099 | AJ6: 0.077777 | AK6: 0 | AL6: #########
A7: _Unknown | B7: _Unknown | E7: Unknown | F7: 27 | G7: 27 | H7: 174 | I7: 174 | J7: 0 | K7: 0 | L7: 0 | M7: 0 | N7: 0 | O7: 0 | P7: 0 | Q7: 0 | R7: 0 | S7: 0 | T7: 0 | U7: 0 | V7: 0 | W7: 0 | X7: 0 | Y7: 0 | Z7: 0 | AA7: 2.411099 | AB7: 0.077777 | AC7: 0 | AD7: 0 | AE7: 0 | AF7: 0 | AG7: 0 | AH7: 0 | AI7: 2.411099 | AJ7: 0.077777 | AK7: 0 | AL7: #########
A8: Adult Care_20-25 | B8: Accessories_20-25 | C8: Adult Care | D8: Accessories | E8: 20-25 | F8: 1 | G8: 0 | H8: 4 | I8: 0 | J8: 0 | K8: 0 | L8: 0 | M8: 0 | N8: 0 | O8: 0 | P8: 0 | Q8: 0 | R8: 0 | S8: 0 | T8: 0 | U8: 0 | V8: 0 | W8: 0 | X8: 0 | Y8: 0 | Z8: 0 | AA8: 0.090909 | AB8: 0.030303 | AC8: 0 | AD8: 0 | AE8: 0 | AF8: 0 | AG8: 0 | AH8: 3.468971 | AI8: 3.642425 | AJ8: 4.143407 | AK8: 0 | AL8: #########
A9: Adult Care_25+ | B9: Accessories_25+ | C9: Adult Care | D9: Accessories | E9: 25+ | F9: 6 | G9: 3 | H9: 125 | I9: 37 | J9: 0 | K9: 0.090909 | L9: 1.224026 | M9: 0.090909 | N9: 1 | O9: 0.090909 | P9: 0.090909 | Q9: 0.090909 | R9: 0.090909 | S9: 0.090909 | T9: 0.090909 | U9: 0.090909 | V9: 0.090909 | W9: 0.090909 | X9: 0.090909 | Y9: 0.090909 | Z9: 0 | AA9: 0.090909 | AB9: 0.030303 | AC9: 0 | AD9: 3.642425 | AE9: 4.056103 | AF9: 4.778612 | AG9: 4.236362 | AH9: 3.468971 | AI9: 3.642425 | AJ9: 4.143407 | AK9: 0 | AL9: #########
A10: Gaming_25+ | B10: Accessories_25+ | C10: Gaming | D10: Accessories | E10: 25+ | F10: 6 | G10: 5 | H10: 143 | I10: 14 | J10: 0 | K10: 0 | L10: 0 | M10: 0 | N10: 0 | O10: 0 | P10: 0 | Q10: 0 | R10: 0 | S10: 0 | T10: 0 | U10: 0 | V10: 0 | W10: 0 | X10: 0 | Y10: 0 | Z10: 0 | AA10: 0.090909 | AB10: 0.030303 | AC10: 0 | AD10: 0 | AE10: 0 | AF10: 0 | AG10: 0 | AH10: 0 | AI10: 0 | AJ10: 0 | AK10: 0 | AL10: #########
A11: Adult Care_Unknown | B11: Accessories_Unknown | C11: Adult Care | D11: Accessories | E11: Unknown | F11: 3 | G11: 3 | H11: 41 | I11: 41 | J11: 0 | K11: 0 | L11: 0 | M11: 0 | N11: 0 | O11: 0 | P11: 0 | Q11: 0 | R11: 0 | S11: 0 | T11: 0 | U11: 0 | V11: 0 | W11: 0 | X11: 0 | Y11: 0 | Z11: 0 | AA11: 0.090909 | AB11: 0.030303 | AC11: 0 | AD11: 0 | AE11: 0 | AF11: 0 | AG11: 0 | AH11: 3.468971 | AI11: 3.642425 | AJ11: 4.143407 | AK11: 0 | AL11: #########
A12: Gaming_Unknown | B12: Accessories_Unknown | C12: Gaming | D12: Accessories | E12: Unknown | F12: 1 | G12: 1 | H12: 4 | I12: 4 | J12: 0 | K12: 0 | L12: 0 | M12: 0 | N12: 0 | O12: 0 | P12: 0 | Q12: 0 | R12: 0 | S12: 0 | T12: 0 | U12: 0 | V12: 0 | W12: 0 | X12: 0 | Y12: 0 | Z12: 0 | AA12: 0.090909 | AB12: 0.030303 | AC12: 0 | AD12: 0 | AE12: 0 | AF12: 0 | AG12: 0 | AH12: 0 | AI12: 0 | AJ12: 0 | AK12: 0 | AL12: #########
A13: Toys & Games_0-5 | B13: Activity Books_0-5 | C13: Toys & Games | D13: Activity Books | E13: 0-5 | F13: 2 | G13: 0 | H13: 56 | I13: 0 | J13: 0.473291 | K13: 0.710589 | L13: 0.486315 | M13: 0.442773 | N13: 0.623107 | O13: 0.267816 | P13: 0.267816 | Q13: 0.267816 | R13: 0.442773 | S13: 0.442773 | T13: 0.267816 | U13: 0.267816 | V13: 0.267816 | W13: 0.442773 | X13: 0.442773 | Y13: 0.355294 | Z13: 0.325397 | AA13: 0.325397 | AB13: 0.410547 | AC13: 0.376988 | AD13: 0.442773 | AE13: 0.442773 | AF13: 0.355294 | AG13: 0.355294 | AH13: 0.03 | AI13: 0.22193 | AJ13: 0.199318 | AK13: 0.355294 | AL13: #########
A14: Toys & Games_10-15 | B14: Activity Books_10-15 | C14: Toys & Games | D14: Activity Books | E14: 46310 | F14: 5 | G14: 0 | H14: 84 | I14: 0 | J14: 2.201923 | K14: 1.130963 | L14: 1.444915 | M14: 0.760965 | N14: 0.672847 | O14: 0.182884 | P14: 0.182884 | Q14: 0.182884 | R14: 0.187114 | S14: 0.760965 | T14: 0.182884 | U14: 0.182884 | V14: 0.182884 | W14: 0.187114 | X14: 0.760965 | Y14: 0.376988 | Z14: 0.325397 | AA14: 0.325397 | AB14: 0.410547 | AC14: 0.376988 | AD14: 0.760965 | AE14: 0.760965 | AF14: 1.224008 | AG14: 0.675455 | AH14: 0.03 | AI14: 0.22193 | AJ14: 0.199318 | AK14: 0.355294 | AL14: #########
A15: Toys & Games_15-20 | B15: Activity Books_15-20 | C15: Toys & Games | D15: Activity Books | E15: 15-20 | F15: 1 | G15: 0 | H15: 132 | I15: 0 | J15: 0 | K15: 0 | L15: 0 | M15: 0 | N15: 0 | O15: 0 | P15: 0 | Q15: 0 | R15: 0 | S15: 0 | T15: 0 | U15: 0 | V15: 0 | W15: 0 | X15: 0 | Y15: 0 | Z15: 0.325397 | AA15: 0.325397 | AB15: 0.410547 | AC15: 0.376988 | AD15: 0.822051 | AE15: 0.822051 | AF15: 0.427692 | AG15: 0.427692 | AH15: 0.03 | AI15: 0.22193 | AJ15: 0.199318 | AK15: 0.355294 | AL15: #########
A16: Toys & Games_20-25 | B16: Activity Books_20-25 | C16: Toys & Games | D16: Activity Books | E16: 20-25 | F16: 3 | G16: 0 | H16: 71 | I16: 0 | J16: 1.29478 | K16: 1.149588 | L16: 0.753493 | M16: 0.804391 | N16: 0.699721 | O16: 0.084483 | P16: 0.084483 | Q16: 0.084483 | R16: 0.260714 | S16: 0.804391 | T16: 0.084483 | U16: 0.084483 | V16: 0.084483 | W16: 0.260714 | X16: 0.804391 | Y16: 0.383196 | Z16: 0.325397 | AA16: 0.325397 | AB16: 0.410547 | AC16: 0.376988 | AD16: 0.260714 | AE16: 0.260714 | AF16: 0.383196 | AG16: 0.383196 | AH16: 0.03 | AI16: 0.22193 | AJ16: 0.199318 | AK16: 0.355294 | AL16: #########
A17: Toys & Games_25+ | B17: Activity Books_25+ | C17: Toys & Games | D17: Activity Books | E17: 25+ | F17: 7 | G17: 0 | H17: 727 | I17: 0 | J17: 0.953968 | K17: 1.589827 | L17: 0.432288 | M17: 1.180952 | N17: 0.742818 | O17: 0.083478 | P17: 0.083478 | Q17: 0.083478 | R17: 0.325397 | S17: 1.180952 | T17: 0.083478 | U17: 0.083478 | V17: 0.083478 | W17: 0.325397 | X17: 1.180952 | Y17: 0.529942 | Z17: 0.325397 | AA17: 0.325397 | AB17: 0.410547 | AC17: 0.376988 | AD17: 0.166667 | AE17: 0.180556 | AF17: 0.293106 | AG17: 0.298081 | AH17: 0.03 | AI17: 0.22193 | AJ17: 0.199318 | AK17: 0.355294 | AL17: #########
A18: Toys & Games_5-10 | B18: Activity Books_5-10 | C18: Toys & Games | D18: Activity Books | E18: 46300 | F18: 2 | G18: 0 | H18: 25 | I18: 0 | J18: 0.076923 | K18: 0.345594 | L18: 0.656876 | M18: 0.345594 | N18: 1 | O18: 0.345594 | P18: 0.345594 | Q18: 0.345594 | R18: 0.345594 | S18: 0.345594 | T18: 0.345594 | U18: 0.345594 | V18: 0.345594 | W18: 0.345594 | X18: 0.345594 | Y18: 0.345594 | Z18: 0.325397 | AA18: 0.325397 | AB18: 0.410547 | AC18: 0.376988 | AD18: 0.345594 | AE18: 0.345594 | AF18: 0.371547 | AG18: 0.384524 | AH18: 0.03 | AI18: 0.22193 | AJ18: 0.199318 | AK18: 0.355294 | AL18: #########
A19: Mobile Accessories_25+ | B19: Adapters_25+ | C19: Mobile Accessories | D19: Adapters | E19: 25+ | F19: 1 | G19: 1 | H19: 18 | I19: 18 | J19: 0 | K19: 0 | L19: 0 | M19: 0 | N19: 0 | O19: 0 | P19: 0 | Q19: 0 | R19: 0 | S19: 0 | T19: 0 | U19: 0 | V19: 0 | W19: 0 | X19: 0 | Y19: 0 | Z19: 0 | AA19: 0 | AB19: 0 | AC19: 0 | AD19: 0 | AE19: 0 | AF19: 0 | AG19: 0 | AH19: 0 | AI19: 0 | AJ19: 0 | AK19: 0 | AL19: #########
A20: Health & Wellness_20-25 | B20: Adult Diapers_20-25 | C20: Health & Wellness | D20: Adult Diapers | E20: 20-25 | F20: 1 | G20: 0 | H20: 68 | I20: 0 | J20: 0 | K20: 0 | L20: 0 | M20: 0 | N20: 0 | O20: 0 | P20: 0 | Q20: 0 | R20: 0 | S20: 0 | T20: 0 | U20: 0 | V20: 0 | W20: 0 | X20: 0 | Y20: 0 | Z20: 0.651892 | AA20: 0.737931 | AB20: 0.638584 | AC20: 0 | AD20: 1.632011 | AE20: 2.067834 | AF20: 3.67977 | AG20: 2.082105 | AH20: 0.505845 | AI20: 1.213843 | AJ20: 2.057336 | AK20: 1.071261 | AL20: #########
A21: Health & Wellness_25+ | B21: Adult Diapers_25+ | C21: Health & Wellness | D21: Adult Diapers | E21: 25+ | F21: 6 | G21: 0 | H21: 1029 | I21: 0 | J21: 2.579121 | K21: 3.192918 | L21: 2.394213 | M21: 1.260036 | N21: 0.394635 | O21: 0.543059 | P21: 0.543059 | Q21: 0.651892 | R21: 0.737931 | S21: 0.737931 | T21: 0.543059 | U21: 0.543059 | V21: 0.651892 | W21: 0.737931 | X21: 0.737931 | Y21: 0.798229 | Z21: 0.651892 | AA21: 0.737931 | AB21: 0.638584 | AC21: 0 | AD21: 0.637037 | AE21: 0.710256 | AF21: 1.319861 | AG21: 0.798229 | AH21: 0.505845 | AI21: 1.213843 | AJ21: 2.057336 | AK21: 1.071261 | AL21: #########
A22: Health & Wellness_Unknown | B22: Adult Diapers_Unknown | C22: Health & Wellness | D22: Adult Diapers | E22: Unknown | F22: 0 | G22: 0 | H22: 0 | I22: 0 | J22: 0 | K22: 0 | L22: 0 | M22: 0 | N22: 0 | O22: 0 | P22: 0 | Q22: 0 | R22: 0 | S22: 0 | T22: 0 | U22: 0 | V22: 0 | W22: 0 | X22: 0 | Y22: 0 | Z22: 0.651892 | AA22: 0.737931 | AB22: 0.638584 | AC22: 0 | AD22: 0 | AE22: 0 | AF22: 0 | AG22: 0 | AH22: 0.505845 | AI22: 1.213843 | AJ22: 2.057336 | AK22: 1.071261 | AL22: #########
A23: Cleaning & Household_10-15 | B23: Air fresheners & Candles_10-15 | C23: Cleaning & Household | D23: Air fresheners & Candles | E23: 46310 | F23: 6 | G23: 0 | H23: 1822 | I23: 0 | J23: 21.52431 | K23: 21.55762 | L23: 25.41022 | M23: 12.71697 | N23: 0.589906 | O23: 0 | P23: 0 | Q23: 0 | R23: 8.840644 | S23: 8.840644 | T23: 8.840644 | U23: 8.840644 | V23: 8.840644 | W23: 12.71697 | X23: 12.71697 | Y23: 5.389405 | Z23: 2.543504 | AA23: 3.862144 | AB23: 4.079673 | AC23: 5.389405 | AD23: 4.894091 | AE23: 5.226643 | AF23: 7.986467 | AG23: 7.2494 | AH23: 3.3173 | AI23: 3.964523 | AJ23: 6.529036 | AK23: 4.965673 | AL23: #########
A24: Cleaning & Household_15-20 | B24: Air fresheners & Candles_15-20 | C24: Cleaning & Household | D24: Air fresheners & Candles | E24: 15-20 | F24: 5 | G24: 0 | H24: 665 | I24: 0 | J24: 5.784799 | K24: 6.218119 | L24: 6.879249 | M24: 6.218119 | N24: 1 | O24: 6.218119 | P24: 6.218119 | Q24: 6.218119 | R24: 6.218119 | S24: 6.218119 | T24: 6.218119 | U24: 6.218119 | V24: 6.218119 | W24: 6.218119 | X24: 6.218119 | Y24: 6.218119 | Z24: 2.543504 | AA24: 3.862144 | AB24: 4.079673 | AC24: 5.389405 | AD24: 5.052628 | AE24: 5.052628 | AF24: 7.842166 | AG24: 6.218119 | AH24: 3.3173 | AI24: 3.964523 | AJ24: 6.529036 | AK24: 4.965673 | AL24: #########
A25: Cleaning & Household_20-25 | B25: Air fresheners & Candles_20-25 | C25: Cleaning & Household | D25: Air fresheners & Candles | E25: 20-25 | F25: 7 | G25: 0 | H25: 3006 | I25: 0 | J25: 34.38314 | K25: 31.21965 | L25: 34.51191 | M25: 11.37155 | N25: 0.364243 | O25: 1.538091 | P25: 3.862144 | Q25: 3.862144 | R25: 5.249068 | S25: 9.198795 | T25: 1.538091 | U25: 3.862144 | V25: 3.862144 | W25: 5.249068 | X25: 9.198795 | Y25: 6.24393 | Z25: 2.543504 | AA25: 3.862144 | AB25: 4.079673 | AC25: 5.389405 | AD25: 3.710598 | AE25: 3.710598 | AF25: 5.805307 | AG25: 6.24393 | AH25: 3.3173 | AI25: 3.964523 | AJ25: 6.529036 | AK25: 4.965673 | AL25: #########
A26: Cleaning & Household_25+ | B26: Air fresheners & Candles_25+ | C26: Cleaning & Household | D26: Air fresheners & Candles | E26: 25+ | F26: 10 | G26: 0 | H26: 3205 | I26: 0 | J26: 22.65445 | K26: 20.46992 | L26: 21.13496 | M26: 8.830748 | N26: 0.431401 | O26: 0.648148 | P26: 0.84 | Q26: 1.614049 | R26: 2.013431 | S26: 2.422359 | T26: 0.84 | U26: 1.614049 | V26: 1.929729 | W26: 2.171454 | X26: 2.513386 | Y26: 1.860902 | Z26: 2.543504 | AA26: 3.862144 | AB26: 4.079673 | AC26: 5.389405 | AD26: 2.441446 | AE26: 2.513386 | AF26: 4.153756 | AG26: 2.063496 | AH26: 3.3173 | AI26: 3.964523 | AJ26: 6.529036 | AK26: 4.965673 | AL26: #########
A27: Cleaning & Household_5-10 | B27: Air fresheners & Candles_5-10 | C27: Cleaning & Household | D27: Air fresheners & Candles | E27: 46300 | F27: 7 | G27: 1 | H27: 2629 | I27: 8 | J27: 35.21262 | K27: 34.76555 | L27: 37.46092 | M27: 16.06862 | N27: 0.4622 | O27: 0 | P27: 0 | Q27: 5.61187 | R27: 5.641307 | S27: 7.443752 | T27: 5.61187 | U27: 5.641307 | V27: 5.641307 | W27: 7.443752 | X27: 7.671792 | Y27: 4.966508 | Z27: 2.543504 | AA27: 3.862144 | AB27: 4.079673 | AC27: 5.389405 | AD27: 4.184219 | AE27: 5.641307 | AF27: 9.07508 | AG27: 5.477437 | AH27: 3.3173 | AI27: 3.964523 | AJ27: 6.529036 | AK27: 4.965673 | AL27: #########
A28: Cleaning & Household_Unknown | B28: Air fresheners & Candles_Unknown | C28: Cleaning & Household | D28: Air fresheners & Candles | E28: Unknown | F28: 1 | G28: 1 | H28: 75 | I28: 75 | J28: 0 | K28: 0 | L28: 0 | M28: 0 | N28: 0 | O28: 0 | P28: 0 | Q28: 0 | R28: 0 | S28: 0 | T28: 0 | U28: 0 | V28: 0 | W28: 0 | X28: 0 | Y28: 0 | Z28: 2.543504 | AA28: 3.862144 | AB28: 4.079673 | AC28: 5.389405 | AD28: 0 | AE28: 0 | AF28: 0 | AG28: 0 | AH28: 3.3173 | AI28: 3.964523 | AJ28: 6.529036 | AK28: 4.965673 | AL28: #########
A29: Home & Outdoor_25+ | B29: Air Purifier_25+ | C29: Home & Outdoor | D29: Air Purifier | E29: 25+ | F29: 2 | G29: 2 | H29: 3 | I29: 3 | J29: 0 | K29: 0 | L29: 0 | M29: 0 | N29: 0 | O29: 0 | P29: 0 | Q29: 0 | R29: 0 | S29: 0 | T29: 0 | U29: 0 | V29: 0 | W29: 0 | X29: 0 | Y29: 0 | Z29: 0 | AA29: 0 | AB29: 0 | AC29: 0 | AD29: 0.3 | AE29: 0.750182 | AF29: 1.37915 | AG29: 0.24636 | AH29: 0.625309 | AI29: 1.101178 | AJ29: 1.968989 | AK29: 0.808292 | AL29: #########
A30: Home & Outdoor_Unknown | B30: Air Purifier_Unknown | C30: Home & Outdoor | D30: Air Purifier | E30: Unknown | F30: 1 | G30: 1 | H30: 4 | I30: 4 | J30: 0 | K30: 0 | L30: 0 | M30: 0 | N30: 0 | O30: 0 | P30: 0 | Q30: 0 | R30: 0 | S30: 0 | T30: 0 | U30: 0 | V30: 0 | W30: 0 | X30: 0 | Y30: 0 | Z30: 0 | AA30: 0 | AB30: 0 | AC30: 0 | AD30: 0 | AE30: 0 | AF30: 0 | AG30: 0 | AH30: 0.625309 | AI30: 1.101178 | AJ30: 1.968989 | AK30: 0.808292 | AL30: #########
A31: Headphones_25+ | B31: Airpods_25+ | C31: Headphones | D31: Airpods | E31: 25+ | F31: 2 | G31: 2 | H31: 11 | I31: 11 | J31: 0 | K31: 0 | L31: 0 | M31: 0 | N31: 0 | O31: 0 | P31: 0 | Q31: 0 | R31: 0 | S31: 0 | T31: 0 | U31: 0 | V31: 0 | W31: 0 | X31: 0 | Y31: 0 | Z31: 0 | AA31: 0 | AB31: 0 | AC31: 0 | AD31: 0 | AE31: 0 | AF31: 0 | AG31: 0 | AH31: 0 | AI31: 0 | AJ31: 0 | AK31: 0 | AL31: #########
A32: Mobiles_Unknown | B32: Android Smartphone_Unknown | C32: Mobiles | D32: Android Smartphone | E32: Unknown | F32: 4 | G32: 4 | H32: 8 | I32: 8 | J32: 0 | K32: 0 | L32: 0 | M32: 0 | N32: 0 | O32: 0 | P32: 0 | Q32: 0 | R32: 0 | S32: 0 | T32: 0 | U32: 0 | V32: 0 | W32: 0 | X32: 0 | Y32: 0 | Z32: 0 | AA32: 0 | AB32: 0 | AC32: 0 | AD32: 0 | AE32: 0 | AF32: 0 | AG32: 0 | AH32: 0 | AI32: 0 | AJ32: 0 | AK32: 0 | AL32: #########
A33: Tablets_Unknown | B33: Apple iPads_Unknown | C33: Tablets | D33: Apple iPads | E33: Unknown | F33: 0 | G33: 0 | H33: 0 | I33: 0 | J33: 0 | K33: 0 | L33: 0 | M33: 0 | N33: 0 | O33: 0 | P33: 0 | Q33: 0 | R33: 0 | S33: 0 | T33: 0 | U33: 0 | V33: 0 | W33: 0 | X33: 0 | Y33: 0 | Z33: 0 | AA33: 0 | AB33: 0 | AC33: 0 | AD33: 0 | AE33: 0 | AF33: 0 | AG33: 0 | AH33: 0 | AI33: 0 | AJ33: 0 | AK33: 0 | AL33: #########
A34: Wearables_Unknown | B34: Apple Watch_Unknown | C34: Wearables | D34: Apple Watch | E34: Unknown | F34: 0 | G34: 0 | H34: 0 | I34: 0 | J34: 0 | K34: 0 | L34: 0 | M34: 0 | N34: 0 | O34: 0 | P34: 0 | Q34: 0 | R34: 0 | S34: 0 | T34: 0 | U34: 0 | V34: 0 | W34: 0 | X34: 0 | Y34: 0 | Z34: 0 | AA34: 0 | AB34: 0 | AC34: 0 | AD34: 0 | AE34: 0 | AF34: 0 | AG34: 0 | AH34: 0 | AI34: 0 | AJ34: 0 | AK34: 0 | AL34: #########
A35: Kitchenware_10-15 | B35: Appliances_10-15 | C35: Kitchenware | D35: Appliances | E35: 46310 | F35: 1 | G35: 0 | H35: 450 | I35: 0 | J35: 3.269231 | K35: 3.770451 | L35: 3.88997 | M35: 3.770451 | N35: 1 | O35: 3.770451 | P35: 3.770451 | Q35: 3.770451 | R35: 3.770451 | S35: 3.770451 | T35: 3.770451 | U35: 3.770451 | V35: 3.770451 | W35: 3.770451 | X35: 3.770451 | Y35: 3.770451 | Z35: 0 | AA35: 1.841635 | AB35: 0.416949 | AC35: 1.841635 | AD35: 3.770451 | AE35: 3.770451 | AF35: 3.770451 | AG35: 3.770451 | AH35: 0 | AI35: 1.207407 | AJ35: 0.804599 | AK35: 0 | AL35: #########
A36: Kitchenware_20-25 | B36: Appliances_20-25 | C36: Kitchenware | D36: Appliances | E36: 20-25 | F36: 1 | G36: 0 | H36: 269 | I36: 0 | J36: 1.767399 | K36: 1.841635 | L36: 2.00796 | M36: 1.841635 | N36: 1 | O36: 1.841635 | P36: 1.841635 | Q36: 1.841635 | R36: 1.841635 | S36: 1.841635 | T36: 1.841635 | U36: 1.841635 | V36: 1.841635 | W36: 1.841635 | X36: 1.841635 | Y36: 1.841635 | Z36: 0 | AA36: 1.841635 | AB36: 0.416949 | AC36: 1.841635 | AD36: 1.841635 | AE36: 1.841635 | AF36: 1.841635 | AG36: 1.841635 | AH36: 0 | AI36: 1.207407 | AJ36: 0.804599 | AK36: 0 | AL36: #########
A37: Kitchenware_25+ | B37: Appliances_25+ | C37: Kitchenware | D37: Appliances | E37: 25+ | F37: 6 | G37: 4 | H37: 124 | I37: 13 | J37: 0.607143 | K37: 0.642157 | L37: 0.508167 | M37: 0.642157 | N37: 1 | O37: 0 | P37: 0 | Q37: 0 | R37: 0 | S37: 0 | T37: 0.642157 | U37: 0.642157 | V37: 0.642157 | W37: 0.642157 | X37: 0.642157 | Y37: 0.08027 | Z37: 0 | AA37: 1.841635 | AB37: 0.416949 | AC37: 1.841635 | AD37: 0 | AE37: 0.642157 | AF37: 0.064216 | AG37: 0 | AH37: 0 | AI37: 1.207407 | AJ37: 0.804599 | AK37: 0 | AL37: #########
A38: Kitchenware_Unknown | B38: Appliances_Unknown | C38: Kitchenware | D38: Appliances | E38: Unknown | F38: 0 | G38: 0 | H38: 0 | I38: 0 | J38: 0 | K38: 0 | L38: 0 | M38: 0 | N38: 0 | O38: 0 | P38: 0 | Q38: 0 | R38: 0 | S38: 0 | T38: 0 | U38: 0 | V38: 0 | W38: 0 | X38: 0 | Y38: 0 | Z38: 0 | AA38: 1.841635 | AB38: 0.416949 | AC38: 1.841635 | AD38: 0 | AE38: 0 | AF38: 0 | AG38: 0 | AH38: 0 | AI38: 1.207407 | AJ38: 0.804599 | AK38: 0 | AL38: #########
A39: Bakery_0-5 | B39: Arabic & Flat Bread_0-5 | C39: Bakery | D39: Arabic & Flat Bread | E39: 0-5 | F39: 12 | G39: 0 | H39: 3242 | I39: 0 | J39: 570.2631 | K39: 567.4886 | L39: 566.1628 | M39: 290.9808 | N39: 0.512752 | O39: 17.63182 | P39: 28.40774 | Q39: 32.36113 | R39: 45.04631 | S39: 55.13658 | T39: 17.63182 | U39: 28.40774 | V39: 32.36113 | W39: 45.04631 | X39: 55.13658 | Y39: 63.05429 | Z39: 6.176916 | AA39: 28.40774 | AB39: 22.48322 | AC39: 12.90542 | AD39: 32.04884 | AE39: 36.00952 | AF39: 51.36789 | AG39: 52.47537 | AH39: 2.906413 | AI39: 12.98823 | AJ39: 17.4248 | AK39: 3.682801 | AL39: #########
A40: Bakery_10-15 | B40: Arabic & Flat Bread_10-15 | C40: Bakery | D40: Arabic & Flat Bread | E40: 46310 | F40: 3 | G40: 0 | H40: 285 | I40: 0 | J40: 21.19062 | K40: 23.22276 | L40: 23.66081 | M40: 17.04584 | N40: 0.734015 | O40: 6.176916 | P40: 6.176916 | Q40: 6.176916 | R40: 17.04584 | S40: 17.04584 | T40: 6.176916 | U40: 6.176916 | V40: 6.176916 | W40: 17.04584 | X40: 17.04584 | Y40: 11.61138 | Z40: 6.176916 | AA40: 28.40774 | AB40: 22.48322 | AC40: 12.90542 | AD40: 8.714901 | AE40: 8.714901 | AF40: 18.91489 | AG40: 9.997978 | AH40: 2.906413 | AI40: 12.98823 | AJ40: 17.4248 | AK40: 3.682801 | AL40: #########
...

Sheet New Launch Success Rate
A1: Subcat_ASP Bucket | B1: Total New Launches (Last 180d) | C1: Successful Launches | D1: Aggregation Level Used | E1: Launch Success Rate | F1: Revised
A2: Accessories_20-25 | B2: 3 | C2: 2 | D2: Fallback: ParentCategory | E2: 0.667 | F2: =if(D2="Fallback: ParentCategory_ASP",E2*0.75, IF(D2="Fallback: ParentCategory",E2*0.5,E2)) -> 0.3335
A3: Accessories_25+ | B3: 0 | C3: 0 | D3: No Launches in Entire Category | E3: Not Applicable | F3: =if(D3="Fallback: ParentCategory_ASP",E3*0.75, IF(D3="Fallback: ParentCategory",E3*0.5,E3)) -> Not Applicable
A4: Accessories_25+ | B4: 3 | C4: 2 | D4: Fallback: ParentCategory_ASP | E4: 0.667 | F4: =if(D4="Fallback: ParentCategory_ASP",E4*0.75, IF(D4="Fallback: ParentCategory",E4*0.5,E4)) -> 0.50025
A5: Accessories_Unknown | B5: 3 | C5: 2 | D5: Fallback: ParentCategory | E5: 0.667 | F5: =if(D5="Fallback: ParentCategory_ASP",E5*0.75, IF(D5="Fallback: ParentCategory",E5*0.5,E5)) -> 0.3335
A6: Accessories_Unknown | B6: 0 | C6: 0 | D6: No Launches in Entire Category | E6: Not Applicable | F6: =if(D6="Fallback: ParentCategory_ASP",E6*0.75, IF(D6="Fallback: ParentCategory",E6*0.5,E6)) -> Not Applicable
A7: Activity Books_0-5 | B7: 97 | C7: 70 | D7: Fallback: ParentCategory | E7: 0.722 | F7: =if(D7="Fallback: ParentCategory_ASP",E7*0.75, IF(D7="Fallback: ParentCategory",E7*0.5,E7)) -> 0.361
A8: Activity Books_10-15 | B8: 3 | C8: 3 | D8: Exact Subcat_ASP Match | E8: 1 | F8: =if(D8="Fallback: ParentCategory_ASP",E8*0.75, IF(D8="Fallback: ParentCategory",E8*0.5,E8)) -> 1
A9: Activity Books_15-20 | B9: 97 | C9: 70 | D9: Fallback: ParentCategory | E9: 0.722 | F9: =if(D9="Fallback: ParentCategory_ASP",E9*0.75, IF(D9="Fallback: ParentCategory",E9*0.5,E9)) -> 0.361
A10: Activity Books_20-25 | B10: 3 | C10: 3 | D10: Exact Subcat_ASP Match | E10: 1 | F10: =if(D10="Fallback: ParentCategory_ASP",E10*0.75, IF(D10="Fallback: ParentCategory",E10*0.5,E10)) -> 1
A11: Activity Books_25+ | B11: 3 | C11: 3 | D11: Exact Subcat_ASP Match | E11: 1 | F11: =if(D11="Fallback: ParentCategory_ASP",E11*0.75, IF(D11="Fallback: ParentCategory",E11*0.5,E11)) -> 1
A12: Activity Books_5-10 | B12: 97 | C12: 70 | D12: Fallback: ParentCategory | E12: 0.722 | F12: =if(D12="Fallback: ParentCategory_ASP",E12*0.75, IF(D12="Fallback: ParentCategory",E12*0.5,E12)) -> 0.361
A13: Adapters_25+ | B13: 1 | C13: 0 | D13: Fallback: ParentCategory | E13: Not Applicable | F13: =if(D13="Fallback: ParentCategory_ASP",E13*0.75, IF(D13="Fallback: ParentCategory",E13*0.5,E13)) -> #VALUE!
A14: Adult Diapers_20-25 | B14: 6 | C14: 6 | D14: Fallback: ParentCategory_ASP | E14: 1 | F14: =if(D14="Fallback: ParentCategory_ASP",E14*0.75, IF(D14="Fallback: ParentCategory",E14*0.5,E14)) -> 0.75
A15: Adult Diapers_25+ | B15: 27 | C15: 24 | D15: Fallback: ParentCategory_ASP | E15: 0.889 | F15: =if(D15="Fallback: ParentCategory_ASP",E15*0.75, IF(D15="Fallback: ParentCategory",E15*0.5,E15)) -> 0.66675
A16: Adult Diapers_Unknown | B16: 4 | C16: 0 | D16: Fallback: ParentCategory_ASP | E16: 0 | F16: =if(D16="Fallback: ParentCategory_ASP",E16*0.75, IF(D16="Fallback: ParentCategory",E16*0.5,E16)) -> 0
A17: Air Purifier_25+ | B17: 12 | C17: 3 | D17: Fallback: ParentCategory_ASP | E17: 0.25 | F17: =if(D17="Fallback: ParentCategory_ASP",E17*0.75, IF(D17="Fallback: ParentCategory",E17*0.5,E17)) -> 0.1875
A18: Air Purifier_Unknown | B18: 9 | C18: 0 | D18: Fallback: ParentCategory_ASP | E18: 0 | F18: =if(D18="Fallback: ParentCategory_ASP",E18*0.75, IF(D18="Fallback: ParentCategory",E18*0.5,E18)) -> 0
A19: Air fresheners & Candles_10-15 | B19: 8 | C19: 7 | D19: Fallback: ParentCategory_ASP | E19: 0.875 | F19: =if(D19="Fallback: ParentCategory_ASP",E19*0.75, IF(D19="Fallback: ParentCategory",E19*0.5,E19)) -> 0.65625
A20: Air fresheners & Candles_15-20 | B20: 5 | C20: 3 | D20: Fallback: ParentCategory_ASP | E20: 0.6 | F20: =if(D20="Fallback: ParentCategory_ASP",E20*0.75, IF(D20="Fallback: ParentCategory",E20*0.5,E20)) -> 0.45
A21: Air fresheners & Candles_20-25 | B21: 5 | C21: 4 | D21: Fallback: ParentCategory_ASP | E21: 0.8 | F21: =if(D21="Fallback: ParentCategory_ASP",E21*0.75, IF(D21="Fallback: ParentCategory",E21*0.5,E21)) -> 0.6
A22: Air fresheners & Candles_25+ | B22: 5 | C22: 4 | D22: Exact Subcat_ASP Match | E22: 0.8 | F22: =if(D22="Fallback: ParentCategory_ASP",E22*0.75, IF(D22="Fallback: ParentCategory",E22*0.5,E22)) -> 0.8
A23: Air fresheners & Candles_5-10 | B23: 9 | C23: 7 | D23: Fallback: ParentCategory_ASP | E23: 0.778 | F23: =if(D23="Fallback: ParentCategory_ASP",E23*0.75, IF(D23="Fallback: ParentCategory",E23*0.5,E23)) -> 0.5835
A24: Air fresheners & Candles_Unknown | B24: 47 | C24: 35 | D24: Fallback: ParentCategory | E24: 0.745 | F24: =if(D24="Fallback: ParentCategory_ASP",E24*0.75, IF(D24="Fallback: ParentCategory",E24*0.5,E24)) -> 0.3725
A25: Airpods_25+ | B25: 0 | C25: 0 | D25: No Launches in Entire Category | E25: Not Applicable | F25: =if(D25="Fallback: ParentCategory_ASP",E25*0.75, IF(D25="Fallback: ParentCategory",E25*0.5,E25)) -> Not Applicable
A26: Android Smartphone_Unknown | B26: 0 | C26: 0 | D26: No Launches in Entire Category | E26: Not Applicable | F26: =if(D26="Fallback: ParentCategory_ASP",E26*0.75, IF(D26="Fallback: ParentCategory",E26*0.5,E26)) -> Not Applicable
A27: Apple Watch_Unknown | B27: 16 | C27: 0 | D27: Fallback: ParentCategory_ASP | E27: 0 | F27: =if(D27="Fallback: ParentCategory_ASP",E27*0.75, IF(D27="Fallback: ParentCategory",E27*0.5,E27)) -> 0
A28: Apple iPads_Unknown | B28: 0 | C28: 0 | D28: No Launches in Entire Category | E28: Not Applicable | F28: =if(D28="Fallback: ParentCategory_ASP",E28*0.75, IF(D28="Fallback: ParentCategory",E28*0.5,E28)) -> Not Applicable
A29: Appliances_10-15 | B29: 6 | C29: 1 | D29: Fallback: ParentCategory | E29: 0.167 | F29: =if(D29="Fallback: ParentCategory_ASP",E29*0.75, IF(D29="Fallback: ParentCategory",E29*0.5,E29)) -> 0.0835
A30: Appliances_20-25 | B30: 6 | C30: 1 | D30: Fallback: ParentCategory | E30: 0.167 | F30: =if(D30="Fallback: ParentCategory_ASP",E30*0.75, IF(D30="Fallback: ParentCategory",E30*0.5,E30)) -> 0.0835
A31: Appliances_25+ | B31: 4 | C31: 0 | D31: Exact Subcat_ASP Match | E31: 0 | F31: =if(D31="Fallback: ParentCategory_ASP",E31*0.75, IF(D31="Fallback: ParentCategory",E31*0.5,E31)) -> 0
A32: Appliances_Unknown | B32: 6 | C32: 1 | D32: Fallback: ParentCategory | E32: 0.167 | F32: =if(D32="Fallback: ParentCategory_ASP",E32*0.75, IF(D32="Fallback: ParentCategory",E32*0.5,E32)) -> 0.0835
A33: Arabic & Flat Bread_0-5 | B33: 8 | C33: 6 | D33: Fallback: ParentCategory_ASP | E33: 0.75 | F33: =if(D33="Fallback: ParentCategory_ASP",E33*0.75, IF(D33="Fallback: ParentCategory",E33*0.5,E33)) -> 0.5625
A34: Arabic & Flat Bread_10-15 | B34: 21 | C34: 19 | D34: Fallback: ParentCategory_ASP | E34: 0.905 | F34: =if(D34="Fallback: ParentCategory_ASP",E34*0.75, IF(D34="Fallback: ParentCategory",E34*0.5,E34)) -> 0.67875
A35: Arabic & Flat Bread_15-20 | B35: 17 | C35: 16 | D35: Fallback: ParentCategory_ASP | E35: 0.941 | F35: =if(D35="Fallback: ParentCategory_ASP",E35*0.75, IF(D35="Fallback: ParentCategory",E35*0.5,E35)) -> 0.70575
A36: Arabic & Flat Bread_20-25 | B36: 4 | C36: 4 | D36: Fallback: ParentCategory_ASP | E36: 1 | F36: =if(D36="Fallback: ParentCategory_ASP",E36*0.75, IF(D36="Fallback: ParentCategory",E36*0.5,E36)) -> 0.75
A37: Arabic & Flat Bread_25+ | B37: 5 | C37: 4 | D37: Fallback: ParentCategory_ASP | E37: 0.8 | F37: =if(D37="Fallback: ParentCategory_ASP",E37*0.75, IF(D37="Fallback: ParentCategory",E37*0.5,E37)) -> 0.6
A38: Arabic & Flat Bread_5-10 | B38: 25 | C38: 21 | D38: Fallback: ParentCategory_ASP | E38: 0.84 | F38: =if(D38="Fallback: ParentCategory_ASP",E38*0.75, IF(D38="Fallback: ParentCategory",E38*0.5,E38)) -> 0.63
A39: Arabic & Flat Bread_Unknown | B39: 80 | C39: 70 | D39: Fallback: ParentCategory | E39: 0.875 | F39: =if(D39="Fallback: ParentCategory_ASP",E39*0.75, IF(D39="Fallback: ParentCategory",E39*0.5,E39)) -> 0.4375
A40: Arabic Sweets_10-15 | B40: 21 | C40: 19 | D40: Fallback: ParentCategory_ASP | E40: 0.905 | F40: =if(D40="Fallback: ParentCategory_ASP",E40*0.75, IF(D40="Fallback: ParentCategory",E40*0.5,E40)) -> 0.67875
...

Sheet Main Working
BC3: M3 | BN3: Threshold | BO3: 50
B5: 📥 CM INPUTS + AUTO | T5: SCORE 1: CQ | Vel 40% + Sat 40% + Launch 20% | AL5: Score 2: Category Health | AS5: SCORE 3: SP
T6: 1A. VELOCITY | X6: 1B. SATURATION | AG6: 1C. LAUNCH | AJ6: CQ | AL6: 2A. NMI | AQ6: CH | AS6: SP | AV6: SP | BH6: Accuracy calculation for SKUs available for >30% time in Feb First half
A7: Ship Tp | B7: SKU Name | C7: Category | D7: Subcategory | E7: Supplier | F7: MOQ | G7: ASP | H7: RTV Terms | I7: Monetisation Terms | J7: Shelf Life | K7: New Format? | L7: New Brand? | M7: New Flavour? | N7: New Size? | O7: New Ingredient? | P7: New Price Point? | Q7: Subcat ASP Key | R7: ASP Bucket | S7: Width or Depth | T7: Vel Floor | U7: Benchmark | V7: Vel Score | X7: Conc Index | Y7: Conc Level | Z7: Cat- ASP Median SKU EFF | AA7: SKU Eff | AB7: SKU Eff | AC7: Width or Depth | AD7: Key | AE7: Sat Score | AG7: Launch Success % | AH7: Launch Score | AJ7: CQ SCORE | AL7: NMI Unit% | AM7: 2A | AN7: NMI SKU% | AO7: 2B | AQ7: CH SCORE | AS7: Return Score | AT7: Mon Score | AV7: SP SCORE | AX7: Final Score | AY7: Range | AZ7: Range2 | BA7: Availability | BB7: Total SKU | BC7: Jan ROS | BD7: Feb ROS | BE7: Bucket P10 MV ROS | BF7: Success | BG7: TP CQ | BH7: SCore Range | BI7: Total SKUs | BJ7: Success | BK7: Fail | BL7: Correct Prediction | BM7: Accuracy | BO7: True Positives | BQ7: Result | BS7: CQ Score
A8: DC | B8: Kamasutra Condom Ultrathin Pack of 3 pcs | C8: Adult Care | D8: Condoms | E8: Blue Ocean General Trading LLC | F8: 1 | G8: 7.179167 | H8: Yes | J8: 730 | Q8: =D8&"_"&R8 -> Condoms_5-10 | R8: =IF(G8<5,"0-5",IF(G8<10,"5-10",IF(G8<15,"10-15",IF(G8<20,"15-20",IF(G8<25,"20-25","25+"))))) -> 5-10 | S8: {=XLOOKUP(B8,Availability!K:K,Availability!Q:Q)} -> Depth | T8: =If(OR(A8="DC",A8="Careem DC"),MAX(F8,150)/(60),MAX(F8,80)/(J8*0.5)) -> 2.5 | U8: {=iferror(XLOOKUP(Q8,'Refrence Data'!B:B,'Refrence Data'!W:W),"NA")} -> 11.62304 | V8: =IFERROR(IF(OR(T8=0,U8=0),0,IF(U8/T8>=1,100,IF(U8/T8>=0.75,75,IF(U8/T8>=0.5,50,IF(U8/T8>=0.25,25,0))))), "NA") -> 100 | X8: {=IFERROR(XLOOKUP(Q8,'Refrence Data'!B:B,'Refrence Data'!N:N),"NA")} -> 0.504094 | Y8: =IF(X8>0.8,"HIGH",IF(X8>0.5,"MEDIUM","LOW")) -> MEDIUM | Z8: {=XLOOKUP(Q8,'Refrence Data'!B:B,'Refrence Data'!AG:AG)} -> 7.685756 | AA8: {=IFERROR(XLOOKUP(Q8,'Refrence Data'!B:B,'Refrence Data'!Y:Y),"NA")} -> 7.685756 | AB8: =IF(AA8<Z8*0.5,"Low","High") -> High | AC8: =S8 -> Depth | AD8: =Y8&AB8&AC8 -> MEDIUMHighDepth | AE8: {=XLOOKUP(AD8,'Category Saturation'!A:A,'Category Saturation'!E:E)} -> 60 | AG8: {=iferror(XLOOKUP(Q8,'New Launch Success Rate'!A:A,'New Launch Success Rate'!F:F),"NA")} -> 0.3335 | AH8: =if(OR(AG8="Not Applicable",AG8="NA"),"NA",IF(AG8<10%,0,IF(AG8<25%,25,IF(AG8<50%,50,IF(AG8<80%,75,100))))) -> 50 | AJ8: =if(AH8="NA",(V8*60%+AE8*40%),(V8*60%+AE8*30%+AH8*10%)) -> 83 | AL8: {=XLOOKUP(Q8,'Non Moving'!C:C,'Non Moving'!I:I)/100} -> 0 | AM8: =IF(AL8<0.05,100,IF(AL8<0.1,75,IF(AL8<0.25,50,0))) -> 100 | AN8: {=XLOOKUP(Q8,'Non Moving'!C:C,'Non Moving'!F:F)/100} -> 0 | AO8: =IF(AN8<0.05,100,IF(AN8<0.1,75,IF(AN8<0.25,50,0))) -> 100 | AQ8: =AM8*0.5+AO8*0.5 -> 100 | AS8: =IF(H8="Yes",100,0) -> 100 | AT8: {=iferror(XLOOKUP(I8,Monetization!A:A,Monetization!B:B),25)} -> 25 | AV8: =AS8*0.7+AT8*0.3 -> 77.5 | AX8: =AJ8*1+AQ8*0+AV8*0 -> 83 | AY8: =IF(AX8<25,"0-25",IF(AX8<50,"25-50",IF(AX8<75,"50-75","75-100"))) -> 75-100 | AZ8: =IF(AJ8<25,"0-25",IF(AJ8<50,"25-50",IF(AJ8<75,"50-75","75-100"))) -> 75-100 | BA8: {=iferror(XLOOKUP(B8,Availability!A:A,Availability!E:E),0%)} -> 0.02 | BB8: 1 | BC8: {=XLOOKUP(B8,ROS!C:C,ROS!O:O)} -> 0 | BD8: {=IFERROR(XLOOKUP(B8,ROS!Z:Z,ROS!AA:AA),0)} -> 0 | BE8: {=XLOOKUP(Q8,'Refrence Data'!B:B,'Refrence Data'!T:T)} -> 11.43423 | BF8: =IF(max(BD8,BC8)>max(min(BE8,T8),1),1,0) -> 0 | BG8: =if(BA8>70%, IF(AND(AJ8>$BO$3,BF8=1),"TP",IF(AND(AJ8>$BO$3,BF8=0),"FP",IF(AND(AJ8<$BO$3,BF8=0), "TN", "FN"))),"") | BH8: 0-25 | BI8: =SUMIFS(BB:BB,AY:AY,BH8,BA:BA,">30%") -> 6 | BJ8: =SUMIFS(BF:BF,AY:AY,BH8,BA:BA,">30%") -> 2 | BK8: =BI8-BJ8 -> 4 | BL8: =BK8 -> 4 | BM8: =BL8/BI8 -> 0.66666667 | BO8: =if(BA8>70%, IF(AND(AX8>$BO$3,BF8=1),"TP",IF(AND(AX8>$BO$3,BF8=0),"FP",IF(AND(AX8<$BO$3,BF8=0), "TN", "FN"))),"") | BQ8: TP | BR8: =COUNTIFS(BO:BO,BQ8) -> 69 | BS8: =COUNTIFS(BG:BG,BQ8) -> 69
A9: DC | B9: Kamasutra Condom Ribbed Pack of 3 pcs | C9: Adult Care | D9: Condoms | E9: Blue Ocean General Trading LLC | F9: 1 | G9: 5.895021 | H9: Yes | J9: 730 | Q9: =D9&"_"&R9 -> Condoms_5-10 | R9: =IF(G9<5,"0-5",IF(G9<10,"5-10",IF(G9<15,"10-15",IF(G9<20,"15-20",IF(G9<25,"20-25","25+"))))) -> 5-10 | S9: {=XLOOKUP(B9,Availability!K:K,Availability!Q:Q)} -> Depth | T9: =If(OR(A9="DC",A9="Careem DC"),MAX(F9,150)/(60),MAX(F9,80)/(J9*0.5)) -> 2.5 | U9: {=iferror(XLOOKUP(Q9,'Refrence Data'!B:B,'Refrence Data'!W:W),"NA")} -> 11.62304 | V9: =IFERROR(IF(OR(T9=0,U9=0),0,IF(U9/T9>=1,100,IF(U9/T9>=0.75,75,IF(U9/T9>=0.5,50,IF(U9/T9>=0.25,25,0))))), "NA") -> 100 | X9: {=IFERROR(XLOOKUP(Q9,'Refrence Data'!B:B,'Refrence Data'!N:N),"NA")} -> 0.504094 | Y9: =IF(X9>0.8,"HIGH",IF(X9>0.5,"MEDIUM","LOW")) -> MEDIUM | Z9: {=XLOOKUP(Q9,'Refrence Data'!B:B,'Refrence Data'!AG:AG)} -> 7.685756 | AA9: {=IFERROR(XLOOKUP(Q9,'Refrence Data'!B:B,'Refrence Data'!Y:Y),"NA")} -> 7.685756 | AB9: =IF(AA9<Z9*0.5,"Low","High") -> High | AC9: =S9 -> Depth | AD9: =Y9&AB9&AC9 -> MEDIUMHighDepth | AE9: {=XLOOKUP(AD9,'Category Saturation'!A:A,'Category Saturation'!E:E)} -> 60 | AG9: {=iferror(XLOOKUP(Q9,'New Launch Success Rate'!A:A,'New Launch Success Rate'!F:F),"NA")} -> 0.3335 | AH9: =if(OR(AG9="Not Applicable",AG9="NA"),"NA",IF(AG9<10%,0,IF(AG9<25%,25,IF(AG9<50%,50,IF(AG9<80%,75,100))))) -> 50 | AJ9: =if(AH9="NA",(V9*60%+AE9*40%),(V9*60%+AE9*30%+AH9*10%)) -> 83 | AL9: {=XLOOKUP(Q9,'Non Moving'!C:C,'Non Moving'!I:I)/100} -> 0 | AM9: =IF(AL9<0.05,100,IF(AL9<0.1,75,IF(AL9<0.25,50,0))) -> 100 | AN9: {=XLOOKUP(Q9,'Non Moving'!C:C,'Non Moving'!F:F)/100} -> 0 | AO9: =IF(AN9<0.05,100,IF(AN9<0.1,75,IF(AN9<0.25,50,0))) -> 100 | AQ9: =AM9*0.5+AO9*0.5 -> 100 | AS9: =IF(H9="Yes",100,0) -> 100 | AT9: {=iferror(XLOOKUP(I9,Monetization!A:A,Monetization!B:B),25)} -> 25 | AV9: =AS9*0.7+AT9*0.3 -> 77.5 | AX9: =AJ9*1+AQ9*0+AV9*0 -> 83 | AY9: =IF(AX9<25,"0-25",IF(AX9<50,"25-50",IF(AX9<75,"50-75","75-100"))) -> 75-100 | AZ9: =IF(AJ9<25,"0-25",IF(AJ9<50,"25-50",IF(AJ9<75,"50-75","75-100"))) -> 75-100 | BA9: {=iferror(XLOOKUP(B9,Availability!A:A,Availability!E:E),0%)} -> 0 | BB9: 1 | BC9: {=XLOOKUP(B9,ROS!C:C,ROS!O:O)} -> 0 | BD9: {=IFERROR(XLOOKUP(B9,ROS!Z:Z,ROS!AA:AA),0)} -> 0 | BE9: {=XLOOKUP(Q9,'Refrence Data'!B:B,'Refrence Data'!T:T)} -> 11.43423 | BF9: =IF(max(BD9,BC9)>max(min(BE9,T9),1),1,0) -> 0 | BG9: =if(BA9>70%, IF(AND(AJ9>$BO$3,BF9=1),"TP",IF(AND(AJ9>$BO$3,BF9=0),"FP",IF(AND(AJ9<$BO$3,BF9=0), "TN", "FN"))),"") | BH9: 25-50 | BI9: =SUMIFS(BB:BB,AY:AY,BH9,BA:BA,">30%") -> 44 | BJ9: =SUMIFS(BF:BF,AY:AY,BH9,BA:BA,">30%") -> 11 | BK9: =BI9-BJ9 -> 33 | BL9: =BK9 -> 33 | BM9: =BL9/BI9 -> 0.75 | BO9: =if(BA9>70%, IF(AND(AX9>$BO$3,BF9=1),"TP",IF(AND(AX9>$BO$3,BF9=0),"FP",IF(AND(AX9<$BO$3,BF9=0), "TN", "FN"))),"") | BQ9: TN | BR9: =COUNTIFS(BO:BO,BQ9) -> 25 | BS9: =COUNTIFS(BG:BG,BQ9) -> 25
